Workbook
Name CompanyList: Company_List!$A$3:$A$207
Name DecisionList: Settings!$D$8:$D$10
Name DocumentList: Settings!$I$8:$I$12
Name QuarterList: Settings!$G$8:$G$12
Name RaterList: Settings!$A$8:$A$14
Name SectionList: Settings!$H$8:$H$11
Name TickerList: Company_List!$B$3:$B$207
Name YearList: Settings!$F$8:$F$14

Sheet Start_Here
A1: Start here
A3: What this workbook is | B3: The complete dataset and results for the model arm of the Citibank Applied Research Project. 361 model readings and 420 human readings, with every reported figure and its source.
A4: Read these four tabs first | B4: Results_Summary for every figure with its definition. Charts_Corrected for the figures. Efficiency_Corrected for cost and time. Confusion_Matrices for where the errors are.
A5: The one thing to understand before reading any number | B5: Accuracy is reported two ways from the same correct calls. SELECTIVITY asks whether the model was right when it committed to a direction, and reads 62.4% on 109 graded frozen events. COVERAGE asks whether it captured the available directional information, counts every HOLD on a moving event as a miss, and reads 46.9% on 145. Both are correct. Quoting one without the other is misleading.
A6: Three event sets, and which to quote | B6: FROZEN is 232 events and is the pre-registered primary. Lead with it. EXTENSION is 93 events across 20 companies added on 2026-08-14 and is descriptive only, since it yielded 18 graded events. COMBINED is all 325 and is a robustness check. Every figure in Results_Summary shows all three side by side.
A7: The sample is small and most comparisons are untestable | B7: Every frozen accuracy claim rests on 109 graded events, with a minimum detectable effect of roughly ±11 percentage points. The extension rests on 18, and is smaller again. A non-significant comparison here is underpowered rather than null, and the distinction matters.
A8: Thresholds were fitted in sample | B8: The deployed HOLD thresholds were chosen by maximising a compounded return the study no longer reports, on the full dataset with all events seen, and were not pre-registered. Every threshold-dependent figure carries that qualification. The walk-forward tab tests it.
A9: Two definitions of combined | B9: Main figures use COMBINED-FULL at 325 events. The baseline frontier uses COMBINED-EVAL at 279, because the baselines required a dev split for threshold fitting. Never compare a frontier figure against a non-frontier figure without checking which.
A10: Which tabs are working records rather than results | B10: The provenance and protocol tabs are working records rather than results. Corrections_Log, Findings, Anchor_Audit, Price_Basis_Note and the two superseded re-pricing tabs are referenced in several places but are NOT present in this workbook — they live in the repo. Summary, Charts and Efficiency are the original sheets, retained unchanged; they use the coverage convention and the Charts floor line sits on a different denominator from its bars. Use the corrected equivalents instead.
A11: Before you use it | B11: Open in Excel and press Ctrl+Alt+F9 to force a full recalculation. Several tabs are formula-driven and use XLOOKUP, which does not evaluate outside Excel.
A13: Prepared 14 August 2026; corrections applied through 24 August 2026. Figures on the corrected release_date anchor, frozen set N=232.

Sheet Results_Summary
A1: Results Summary — all three event sets
A2: Every figure appears on three sets. FROZEN (highlighted) is the pre-registered primary at 232 events and is what the written analysis leads with. EXTENSION is the 93 events added on 2026-08-14 across 20 companies the model arm had never scored, and is descriptive only at 18 graded events. COMBINED is all 325 events and is a robustness check, not a replacement. Accuracy is reported under two conventions because they answer different questions and neither travels alone.
A4: Headline result
A5: Metric | B5: FROZEN (primary) | C5: EXTENSION | D5: COMBINED | E5: Definition
A6: Selectivity accuracy | B6: 62.4% (68/109) | C6: 72.2% (13/18) | D6: 63.8% (81/127) | E6: Model committed to a direction AND |return| > 2%
A7: Majority-direction floor | B7: 54.1% | C7: 61.1% | D7: 55.1% | E7: Always predicting the majority realised direction, same denominator
A8: Margin over floor | B8: +8.3pp | C8: +11.1pp | D8: +8.7pp | E8: Accuracy minus its own floor
A9: Coverage accuracy | B9: 46.9% (68/145) | C9: 38.2% (13/34) | D9: 45.3% (81/179) | E9: All events with |return| > 2%; every HOLD counts as a miss
A10: Coverage floor | B10: 54.5% | C10: 50.0% | D10: — | E10: Majority direction on the coverage denominator
A11: Score-return rank correlation | B11: rho 0.2565, p=0.0001 | C11: rho 0.2715 | D11: — | E11: Spearman, blended score against realised overnight return. No threshold, no band, no selection
A12: Mean net per trade | B12: 1.7963% | C12: 1.4885% | D12: 1.7225% | E12: After 10bps round-trip cost
A13: Summed total return | B13: +303.80% | C13: +41.46% | D13: — | E13: Sum of independent per-trade returns. Not compounded, not an achievable balance. NOTE: on the N=233 / 169-trade vintage, not the corrected N=232 / 168 (Corrected_Metrics!F16).
A14: t-statistic on mean net | B14: 3.676 | C14: 1.362 | D14: — | E14: mean / sd × sqrt(n). Not a Sharpe ratio. NOTE: n=169 trades on the N=233 vintage (Corrected_Metrics!D17).
A15: Information ratio per trade | B15: 0.2828 | C15: 0.241 | D15: — | E15: mean / sd, unscaled. NOTE: n=169 trades on the N=233 vintage (Corrected_Metrics!D18).
A16: The two accuracy conventions are not in conflict and come from the same correct calls. Selectivity asks whether the model was right when it committed. Coverage asks whether it captured the available directional information, and it did not, because it stayed silent on 36 frozen events and 16 extension events that moved more than 2%. Quote neither without the other.
A18: Effective sample funnel
A19: Step | B19: FROZEN | C19: EXTENSION | D19: COMBINED | E19: Note
A20: Total scored | B20: 268 | C20: 93 | D20: 361 | E20: Events read by the model
A21: Excluded | B21: 36 | C21: 0 | D21: 36 | E21: 25 worksheet contamination, 1 misattributed document, 1 look-ahead document, 9 timing unresolved
A22: Clean universe | B22: 232 | C22: 93 | D22: 325 | E22: The reported universe
A23: Traded (BUY or SELL) | B23: 168 | C23: 53 | D23: 221 | E23: Trade rate 72.4% frozen against 57.0% extension
A24: Graded directionally | B24: 109 | C24: 18 | D24: 127 | E24: |return| > 2%, inside the pre-registered neutral band otherwise
A25: Correct | B25: 68 | C25: 13 | D25: 81
A26: Every accuracy claim rests on 109 graded events for the frozen set and 18 for the extension. The unpaired minimum detectable effect is roughly ±11pp on the frozen set, and the extension is smaller again, so the extension cannot test accuracy and its figures are descriptive only. The extension trade rate of 57.0% is itself a finding: the model held on 47.1% of extension events that moved more than 2% (16 of 34), against 24.8% on the frozen set (36 of 145).
A28: Signal decay by horizon (FROZEN)
A29: Horizon | B29: Mean net/trade | C29: Accuracy | D29: rho | E29: p (rho) | F29: Graded n
A30: Overnight | B30: 1.7963% | C30: 62.4% | D30: 0.2565 | E30: 0.0001 | F30: 109
A31: 1 day | B31: 1.1832% | C31: 60.2% | D31: 0.1952 | E31: 0.0028 | F31: 113
A32: 3 days | B32: 0.8296% | C32: 52.6% | D32: 0.1353 | E32: 0.0395 | F32: 114
A33: 5 days | B33: 0.9369% | C33: 51.9% | D33: 0.0972 | E33: 0.1401 | F33: 106
A34: 10 days | B34: 1.4455% | C34: 57.0% | D34: 0.0951 | E34: 0.1488 | F34: 114
A35: Mean net per trade declines from 1.80% overnight to a trough of 0.83% at three days and partially recovers by ten (1.45%); the bootstrap interval touches zero at three and five days. The overnight window remains the measured choice; the recovery at ten days leaves longer-horizon drift an open question rather than ruled out. Note that the excess-over-SPY column in returns_matrix.csv is a separate per-event diagnostic and is not monotonic; its shape reflects SPY’s own multi-horizon pattern across those entry dates, not the model.
A37: Human arm versus model (FROZEN)
A38: Comparison | B38: Human | C38: Model | D38: Difference | E38: p | F38: MDE | G38: n
A39: Direction-only, both committed | B39: 57.6% | C39: 58.8% | D39: +1.2pp | E39: 0.889 | F39: ±21pp | G39: 85
A40: Versus always-DOWN floor 52.9% | B40: +4.7pp | C40: +5.9pp | D40: — | E40: 0.224 / 0.164 | F40: — | G40: 85
A41: SELL calls | B41: 72.7% | C41: 69.2% | D41: — | E41: 0.026 / 0.038 | F41: — | G41: 22 / 26
A42: BUY calls | B42: 52.4% | C42: 54.2% | D42: — | E42: 0.401 / 0.301 | F42: — | G42: 63 / 59
A43: Cohen’s kappa | B43: 0.1391 | D43: CI 0.049 to 0.229 | E43: — | F43: — | G43: 170
A44: Neither arm beats the naive floor by a testable margin and the difference between them is untestable rather than absent. Both clear chance on SELL calls and neither clears chance on BUY. Against the base rate rather than 50% the SELL margins soften to p=0.060 and 0.087. Kappa near zero means the two arms are close to independent, which is why their agreement carries no information about accuracy.
...

Sheet Charts_Corrected
A1: Charts — three event sets
A2: Charts on the corrected release_date anchor. Each floor is computed on the same denominator as the bars it sits against. FROZEN is the pre-registered primary; EXTENSION is descriptive only at 18 graded events. The legacy Charts sheet is retained unchanged and uses the coverage convention with a mismatched floor.
A4: 1. Selectivity accuracy against its floor, all three sets
A5: Set | B5: Accuracy | C5: Majority-direction floor
A6: Frozen (n=109) | B6: =B78/B77 | C6: =VALUE(Corrected_Metrics!B11)
A7: Extension (n=18) | B7: 0.722 | C7: 0.611
A8: Combined (n=127) | B8: =D78/D77 | C8: 0.551
A12: 2. Coverage accuracy against its floor
A13: Set | B13: Accuracy | C13: Coverage floor
A14: Frozen (n=145) | B14: =VALUE(Corrected_Metrics!B13) | C14: =VALUE(Corrected_Metrics!B14)
A15: Extension (n=34) | B15: 0.382 | C15: 0.5
A16: Combined (n=179) | B16: =Sector_Breakdown!E29/Sector_Breakdown!D29 | C16: 0.536
A20: 3. Rank correlation decays with horizon (frozen)
A21: Horizon | B21: Rank correlation (rho)
A22: Overnight | B22: 0.257
A23: 1 day | B23: 0.1952
A24: 3 days | B24: 0.1353
A25: 5 days | B25: 0.0972
A26: 10 days | B26: 0.0951
A30: 4. Accuracy and return decay with horizon (frozen)
A31: Horizon | B31: Accuracy | C31: Mean net per trade
A32: Overnight | B32: 0.624 | C32: 0.01796
A33: 1 day | B33: 0.602 | C33: 0.01183
A34: 3 days | B34: 0.526 | C34: 0.00830
A35: 5 days | B35: 0.519 | C35: 0.00937
A36: 10 days | B36: 0.570 | C36: 0.01446
A40: 5. Directional accuracy by call type (170-paired subset; graded on returns_matrix overnight, ±2% band; floor = base rate of that direction among the 97 graded paired events)
A41: Call | B41: Human | C41: Model | D41: Floor for that call
A42: BUY | B42: 0.491 | C42: 0.512 | D42: 0.392
A43: SELL | B43: 0.739 | C43: 0.808 | D43: 0.608
A47: 6. Section ablation — accuracy and cost (frozen)
A48: Arm | B48: Accuracy | C48: Cost per correct call
A49: Full bundle | B49: 0.646 | C49: 0.0369
A50: Press release | B50: 0.649 | C50: 0.0225
A51: Prepared remarks | B51: 0.644 | C51: 0.0187
A52: Q&A only | B52: 0.692 | C52: 0.022
A56: 7. Baseline frontier — conventions differ by column: see notes on the header row
A57: Method | B57: Frozen | C57: Extension | D57: Combined-eval
A58: Majority floor | B58: =VALUE(Corrected_Metrics!B90) | C58: 0.5 | D58: 0.536
A59: Deployed model | B59: =VALUE(Corrected_Metrics!B96) | C59: 0.382 | D59: 0.464
...

Sheet Trader_View
A1: Trader view — the operational questions
A2: The cuts a desk asks for before deploying a signal: does conviction predict reliability, what does the return distribution look like, where is the left tail, does the edge concentrate in large moves, and how does the accuracy-versus-coverage trade-off behave across the whole band rather than at one threshold. All figures are the frozen 232-event universe unless stated.
A4: 1. Does conviction predict reliability?
A5: Score band | B5: Graded n | C5: Correct | D5: Accuracy
A6: SELL, below −0.30 | B6: 18 | C6: 13 | D6: 0.722
A7: SELL, −0.30 to −0.15 | B7: 9 | C7: 7 | D7: 0.778
A8: SELL, −0.15 to −0.10 | B8: 7 | C8: 6 | D8: 0.857
A9: BUY, +0.20 to +0.35 | B9: 43 | C9: 21 | D9: 0.488
A10: BUY, +0.35 to +0.45 | B10: 14 | C10: 9 | D10: 0.643
A11: BUY, above +0.45 | B11: 18 | C11: 12 | D11: 0.667
A13: The two sides behave differently. On the BUY side accuracy rises with conviction, 48.8% to 64.3% to 66.7%, which is what a desk would want for position sizing. On the SELL side it falls as conviction strengthens, 85.7% to 77.8% to 72.2%, so a strong sell signal is no more reliable than a marginal one — though the −0.15 to −0.10 band holds only seven events. The usable statement is unchanged: conviction is weakly informative on BUY calls and uninformative on SELL calls. These six bands tile all 109 graded traded events at the deployed thresholds (+0.20/−0.10), and the counts sum to the 68/109 = 62.4% selectivity headline.
A15: 2. What does the return distribution look like?
A16: Bucket | B16: Trades
A17: Loss worse than −10% | B17: 1
A18: −10% to −5% | B18: 17
A19: −5% to 0% | B19: 48
A20: 0% to +5% | B20: 62
A21: +5% to +10% | B21: 25
A22: Above +10% | B22: 15
A24: Statistic | B24: Value
A25: Mean net per trade | B25: 1.7963%
A26: Median net per trade | B26: +0.950%
A27: Best trade | B27: +32.06%
A28: Worst trade | B28: −14.62%
A29: Losing trades | B29: 66 of 168 (39.3%)
A30: Losses worse than 5% | B30: 18 trades
A31: Losses worse than 10% | B31: 1 trade
A33: The mean sits above the median, so the average is pulled up by the right tail, but not dominated by it: removing the single best trade moves the mean from +1.7963% to +1.615%. Thirty-nine per cent of trades lose money and one loses more than 10%, which is the exposure a desk would size against. This is a positive expectancy with a fat right tail rather than a high win rate.
A35: 3. Does the edge concentrate in large moves?
A36: Move size | B36: Graded n | C36: Accuracy | D36: Mean net per trade
A37: 2% to 5% | B37: 49 | C37: 0.531 | D37: 0.0009
A38: 5% to 10% | B38: 44 | C38: 0.614 | D38: 0.0153
A39: Above 10% | B39: 16 | C39: 0.938 | D39: 0.1398
A41: This is the strongest operational finding in the study. On events that moved more than 10% the model was right 93.8% of the time at a mean of +13.98% per trade, against 53.1% and +0.09% on 2 to 5% moves. The signal is most reliable precisely where the money is. The caveat is that 16 events cannot carry a strong claim and the direction of causation is open: large moves may simply be easier to read because the document language is less ambiguous.
A43: 4. The accuracy-versus-coverage trade-off across the whole band
A44: HOLD band | B44: Graded n | C44: Accuracy
A45: ±0% | B45: 167 | C45: 0.611
A46: ±1% | B46: 137 | C46: 0.620
A47: ±2% (pre-registered) | B47: 109 | C47: 0.624
A48: ±3% | B48: 82 | C48: 0.671
...

Sheet Efficiency_Corrected
A1: Efficiency — corrected figures
A2: Cost and time on the corrected anchor. Model cost is measured per call from the API logs. Human time is recorded reading time per event. The two are different currencies and the comparison is indicative rather than a like-for-like unit cost.
A4: Cost per correct directional call, by section arm (frozen)
A5: Arm | B5: Cost per correct call | C5: Mean tokens
A6: Full bundle | B6: 0.0369 | C6: 30096
A7: Press release | B7: 0.0225 | C7: 13030
A8: Prepared remarks | B8: 0.0187 | C8: 10287
A9: Q&A only | B9: 0.022 | C9: 13163
A13: Human reading time by information set
A14: Information set | B14: Mean minutes | C14: Readings
A15: Press release only | B15: 15 | C15: 19
A16: Guidance only | B16: 18.7 | C16: 29
A17: Presentation only | B17: 19.8 | C17: 23
A18: Financials only | B18: 20.3 | C18: 32
A19: Q&A only | B19: 29.4 | C19: 33
A20: Full document | B20: 29.8 | C20: 190
A21: Transcript only | B21: 33.5 | C21: 94
A25: API cost and break-even
A26: Item | B26: Value | C26: Basis
A27: Extension scoring total | B27: $0.77146 | C27: 93 events, measured per call
A28: Extension ablation total | B28: $1.72383 | C28: 298 calls across four arms
A29: Break-even round trip | B29: 189.63 bps | C29: Mean net per trade, N=232
A30: Deployed cost assumption | B30: 10 bps | C30: Round trip, zero slippage
A32: Per-event token cost is recorded for both sets. Frozen figures come from api_cost_ledger.csv. Extension figures come from the per-issuer first_run_costs.jsonl files, which the ledger builder did not visit until it was corrected on 2026-08-14: it built its issuer list from the frozen naming convention and never matched the extension output folders, so the ledger showed nothing for those 93 events while the data sat on disk. The figures are measured, not allocated averages. No externally-cited realistic desk cost exists in this project, so no claim is made about whether the break-even exceeds realistic trading costs.
A34: Model against human: two currencies, reported separately
A35: Measure | B35: Model arm | C35: Human arm | D35: Note
A36: Correct directional calls | B36: 68 | C36: 155 | D36: Model on 109 graded events; human on 420 readings, re-priced correctness (col AJ; 20 rows carry no re-priced flag)
A37: Total cost | B37: $1.14 | C37: 195.3 hours | D37: API spend against recorded reading time
A38: Per correct call | B38: $0.0369 | C38: 75.6 minutes | D38: The two headline unit figures
A39: Per document | B39: $0.0096 | C39: 27.9 minutes | D39: Mean across all readings
A40: Fastest unit | B40: $0.0187 (prepared remarks) | C40: 17.2 minutes (fastest rater) | D40: Cheapest arm is also the fastest, at 12.09 s median on the extension
A42: Deliberately not converted to a common currency. Turning reading time into money requires choosing an hourly rate, and any resulting ROI figure would inherit that choice rather than measure anything. The two facts stand on their own: the model produces a correct directional call for about three and a half cents, and a human takes about seventy-five minutes. A sensitivity block follows for anyone who wants the conversion, with the rate stated rather than assumed.
A44: Sensitivity: human cost per correct call at various hourly rates
A45: Hourly rate | B45: Cost per correct call | C45: Multiple of model cost
A46: £25 | B46: £31.29 | C46: 848×
A47: £50 | B47: £62.58 | C47: 1,696×
A48: £75 | B48: £93.88 | C48: 2,544×
A49: £100 | B49: £125.17 | C49: 3,392×
A50: £150 | B50: £187.75 | C50: 5,088×
A52: At 75.6 minutes per correct call, the human unit cost is the hourly rate multiplied by 1.260. The multiple against the model assumes $0.0369 per correct call at parity between pound and dollar, so treat it as an order of magnitude rather than a figure. The point is the scale of the gap, which holds across every plausible rate, not the precise number at any one of them.
...

Sheet Confusion_Matrices
A2: (a) Model call vs realised outcome — N=232 clean events, pre-registered ±2% overnight band
B4: Outcome UP (ret>2%) | C4: Outcome FLAT (|ret|≤2%) | D4: Outcome DOWN (ret<-2%) | E4: Row total | F4: Precision (correct/called_dir) | G4: Recall (correct/realised_dir)
A5: Call BUY | B5: =COUNTIFS(LLM_Data_Entry!$BA$3:$BA$354,"YES",LLM_Data_Entry!$H$3:$H$354,"BUY",LLM_Data_Entry!$Q$3:$Q$354,"UP") | C5: =COUNTIFS(LLM_Data_Entry!$BA$3:$BA$354,"YES",LLM_Data_Entry!$H$3:$H$354,"BUY",LLM_Data_Entry!$Q$3:$Q$354,"FLAT") | D5: =COUNTIFS(LLM_Data_Entry!$BA$3:$BA$354,"YES",LLM_Data_Entry!$H$3:$H$354,"BUY",LLM_Data_Entry!$Q$3:$Q$354,"DOWN") | E5: =SUM(B5:D5) | F5: =B5&"/"&E5
A6: Call HOLD | B6: =COUNTIFS(LLM_Data_Entry!$BA$3:$BA$354,"YES",LLM_Data_Entry!$H$3:$H$354,"HOLD",LLM_Data_Entry!$Q$3:$Q$354,"UP") | C6: =COUNTIFS(LLM_Data_Entry!$BA$3:$BA$354,"YES",LLM_Data_Entry!$H$3:$H$354,"HOLD",LLM_Data_Entry!$Q$3:$Q$354,"FLAT") | D6: =COUNTIFS(LLM_Data_Entry!$BA$3:$BA$354,"YES",LLM_Data_Entry!$H$3:$H$354,"HOLD",LLM_Data_Entry!$Q$3:$Q$354,"DOWN") | E6: =SUM(B6:D6) | F6: =C6&"/"&E6
A7: Call SELL | B7: =COUNTIFS(LLM_Data_Entry!$BA$3:$BA$354,"YES",LLM_Data_Entry!$H$3:$H$354,"SELL",LLM_Data_Entry!$Q$3:$Q$354,"UP") | C7: =COUNTIFS(LLM_Data_Entry!$BA$3:$BA$354,"YES",LLM_Data_Entry!$H$3:$H$354,"SELL",LLM_Data_Entry!$Q$3:$Q$354,"FLAT") | D7: =COUNTIFS(LLM_Data_Entry!$BA$3:$BA$354,"YES",LLM_Data_Entry!$H$3:$H$354,"SELL",LLM_Data_Entry!$Q$3:$Q$354,"DOWN") | E7: =SUM(B7:D7) | F7: =D7&"/"&E7
A8: Col total | B8: =SUM(B5:B7) | C8: =SUM(C5:C7) | D8: =SUM(D5:D7) | E8: =SUM(B8:D8)
A9: Recall (correct/total_in_direction) | B9: =B5&"/"&B8 | C9: =C6&"/"&C8 | D9: =D7&"/"&D8
A10: ="Note: BUY-called-DOWN and SELL-called-UP are the costly directional errors. HOLD row against UP and DOWN is the coverage gap ("&(B6+D6)&" events that moved but were passed on). Matrix (a) is computed live from LLM_Data_Entry (In Clean Universe = YES); it previously held figures from a superseded threshold vintage that did not tie to the funnel."
A12: (b) Human arm vs realised outcome — N=170 paired events (section=All, first_rater=YES, in_llm=YES, exclusions applied)
B14: Outcome UP (ret>2%) | C14: Outcome FLAT (|ret|≤2%) | D14: Outcome DOWN (ret<-2%) | E14: Row total
A15: Call BUY | B15: 27 | C15: 40 | D15: 28 | E15: 95
A16: Call HOLD | B16: 5 | C16: 20 | D16: 15 | E16: 40
A17: Call SELL | B17: 6 | C17: 12 | D17: 17 | E17: 35
A18: Col total | B18: 38 | C18: 72 | D18: 60 | E18: 170
A19: Source: human_decisions_export_2026-08-12.csv + returns_matrix.csv
A21: (c) Human vs model agreement — N=170 paired events. Source: kappa_near_independence.csv (the committed CSV still holds the pre-exclusion 171-pair grid; this grid is that crosstab less DIS_FQ1_2025, verified against the paired rows in Human_Data_Entry and by re-running the script at the deployed constants)
A23: Human call \ LLM call | B23: LLM BUY | C23: LLM HOLD | D23: LLM SELL | E23: Row total
A24: Human BUY | B24: 53 | C24: 32 | D24: 10 | E24: =SUM(B24:D24)
A25: Human HOLD | B25: 13 | C25: 8 | D25: 19 | E25: =SUM(B25:D25)
A26: Human SELL | B26: 6 | C26: 13 | D26: 16 | E26: =SUM(B26:D26)
A28: Kappa | B28: 0.1391
A29: 90% CI | B29: [0.049, 0.229]
A30: Observed agreement | B30: 0.4529
A31: Expected agreement | B31: 0.3645

Sheet Item_C_Ablation
A1: PER-ARM ACCURACY AND COST
A2: event_set | B2: arm | C2: n_calls | D2: n_graded | E2: n_correct | F2: accuracy_hold_excluded | G2: mean_tokens_per_call | H2: total_cost_usd | I2: cost_per_call_usd | J2: cost_per_correct_usd
A3: four_arm_n119 | B3: full_bundle | C3: 119 | D3: 48 | E3: 31 | F3: =E3/D3 | G3: 30096 | H3: 1.1441 | I3: 0.0096 | J3: =H3/E3
A4: four_arm_n119 | B4: press_release | C4: 119 | D4: 37 | E4: 24 | F4: =E4/D4 | G4: 13030 | H4: 0.5394 | I4: 0.0045 | J4: =H4/E4
A5: four_arm_n119 | B5: prepared_remarks | C5: 119 | D5: 45 | E5: 29 | F5: =E5/D5 | G5: 10287 | H5: 0.5412 | I5: 0.0045 | J5: =H5/E5
A6: four_arm_n119 | B6: qa_only | C6: 119 | D6: 39 | E6: 27 | F6: =E6/D6 | G6: 13163 | H6: 0.5952 | I6: 0.005 | J6: =H6/E6
A7: all_n200 | B7: full_bundle | C7: 200 | D7: 70 | E7: 46 | F7: =E7/D7 | G7: 33130 | H7: 2.1166 | I7: 0.0106 | J7: =H7/E7
A8: all_n200 | B8: press_release | C8: 200 | D8: 56 | E8: 35 | F8: =E8/D8 | G8: 15298 | H8: 1.0149 | I8: 0.0051 | J8: =H8/E8
A9: all_n200 | B9: prepared_remarks | C9: 119 | D9: 45 | E9: 29 | F9: =E9/D9 | G9: 10287 | H9: 0.5412 | I9: 0.0045 | J9: =H9/E9
A10: all_n200 | B10: qa_only | C10: 119 | D10: 39 | E10: 27 | F10: =E10/D10 | G10: 13163 | H10: 0.5952 | I10: 0.005 | J10: =H10/E10
A12: Note: figures from section_ablation_cost_per_correct.csv DATA ROWS ONLY. four_arm_n119 = events where all 4 arms scored. all_n200 = full scored set for full_bundle and press_release.
A14: PAIRED DIFFERENCES VS FULL BUNDLE
A15: comparison | B15: set | C15: method | D15: n_paired | E15: point_diff | F15: ci_low | G15: ci_high | H15: p_value | I15: metric | J15: note
A16: press_release vs full_bundle | B16: four_arm | C16: strict (both graded) | D16: 36 | E16: 0.0278 | F16: 0.0 | G16: 0.0833 | H16: 0.7162 | I16: accuracy_overnight | J16: On the 36 both-graded events the press release is +2.8pp (p=0.72); the old zero-information identity did not survive the corrected returns
A17: press_release vs full_bundle | B17: four_arm | C17: inclusive (either graded, ungraded=0.5) | D17: 49 | E17: -0.0306 | F17: -0.1020 | G17: 0.0408 | H17: 0.5346 | I17: accuracy_overnight | J17: Full bundle +3.1pp inclusive (p=0.53) — inside the ±12pp paired MDE
A18: prepared_remarks vs full_bundle | B18: four_arm | C18: strict (both graded) | D18: 43 | E18: -0.0233 | F18: -0.0698 | G18: 0.0 | H18: 0.7284 | I18: accuracy_overnight
A19: prepared_remarks vs full_bundle | B19: four_arm | C19: inclusive (either graded, ungraded=0.5) | D19: 50 | E19: -0.0100 | F19: -0.0700 | G19: 0.0400 | H19: 0.8994 | I19: accuracy_overnight
A20: qa_only vs full_bundle | B20: four_arm | C20: strict (both graded) | D20: 38 | E20: 0.0263 | F20: -0.0526 | G20: 0.1053 | H20: 0.7804 | I20: accuracy_overnight
A21: qa_only vs full_bundle | B21: four_arm | C21: inclusive (either graded, ungraded=0.5) | D21: 49 | E21: 0.0102 | F21: -0.0714 | G21: 0.0918 | H21: 0.9390 | I21: accuracy_overnight
A23: Paired MDE ~±12pp. At the promoted constants on the corrected returns no arm separates from the full bundle: the largest inclusive gap is −3.1pp at p=0.53 (press release, n=49). The 2026-08-13 values (−6.8pp at p=0.055 on 66 pairs) came from pre-correction returns at the superseded thresholds and reproduce from no committed input under any pairing convention.
A24: Prepared remarks agrees with the full bundle on 87.4% of signals (104/119) at ~10k tokens.

Sheet Walk_Forward
A2: DEGENERACY FINDING
A4: n_windows | B4: 4
A5: min_trades_floor | B5: 5
A6: objectives_tried | B6: ['mean_net_per_trade', 'directional_accuracy']
A7: degeneracy_finding | B7: {'mean_net_degenerate': 4, 'accuracy_degenerate': 1, 'total_windows': 4, 'both_degenerate': True}
A8: mean_net_objective_n_degenerate | B8: 4
A9: accuracy_objective_n_degenerate | B9: 1
A11: IN-SAMPLE DEPLOYED THRESHOLDS
A13: hold_upper | B13: 0.2
A14: hold_lower | B14: -0.1
A15: n_trades | B15: 168
A16: n_graded | B16: 109
A17: n_correct | B17: 68
A18: accuracy | B18: 0.6239
A19: mean_net_pct | B19: 1.7963
A21: DEV / EVAL SPLIT
A23: Split rule | B23: Sort 232 clean events by release_date (returns_matrix.csv), earliest 20% (46) = dev, remaining 80% (186) = eval.
A24: Eval: accuracy | B24: 63.0% (58/92) | C24: floor=54.6% (65/119 graded) | D24: margin +8.4pp | E24: p=0.064 | F24: MDE ±14.4pp
A25: Dev: accuracy | B25: 58.8% (10/17) | C25: floor=53.8% (14/26 graded) | D25: margin +5.0pp | E25: NOT significant (p=0.436) | F25: MDE ±27.8pp — underpowered
A26: Source | B26: frontier_table.csv, surviving_findings.md
A27: NOT out-of-sample | B27: Dev/eval split applied post hoc to data thresholds were fitted on. Eval 63.0% is in-sample on a subset.
A28: Floor convention (2026-08-21): the dev/eval floors above are computed on all graded events while accuracy is on traded events. On a matched traded-only denominator the dev floor is 11/17 = 64.7% — above the dev accuracy of 58.8% — while eval survives its matched floor (48/92 = 52.2% vs 63.0%). Separately: the MDE figures ±14.4pp/±27.8pp here (and ±10.8pp on Corrected_Metrics) are unreproduced literals from experiments/build_workbook.py, recorded as such (Q3a).
A29: CROSS-ISSUER GENERALISATION (RECONSTRUCTED)
A31: note | B31: Cross-issuer generalisation test: 29 issuers (with clean events in N=232) scored after the N=161 threshold sweep, zero issuer overlap with the 40 in-sweep issuers. 2 further post-sweep issuers (Allianz, Lenovo) are fully timing-excluded. Both subsets span overlapping date ranges (interleaved, not sequential) — this tests issuer transfer, not temporal generalisation. RECONSTRUCTED: sweep membership inferred from issuer ordering and count match (n_documents=161), not from a recorded event list. 453 single-swap alternatives also produce 161.
A33: subset | B33: n_events | C33: n_trades | D33: n_graded | E33: n_correct | F33: accuracy | G33: mean_net_pct | H33: floor | I33: margin | J33: p | K33: mde
A34: in_sweep | B34: 131 | C34: 87 | D34: 50 | E34: 29 | F34: 0.58 | G34: 0.59
A35: post_sweep | B35: 101 | C35: 81 | D35: 59 | E35: 39 | F35: 0.661 | G35: 3.092 | H35: 0.5254 | I35: 13.6 | J35: 0.0244 | K35: 19.5
A37: CAVEATS (three)
A38: 1. RECONSTRUCTED | B38: Sweep membership inferred from issuer ordering and count match (n=161). 453 single-swap alternatives also give n=161.
A39: 2. ISSUER TRANSFER ONLY | B39: Both subsets overlap in time. Tests whether thresholds transfer to new companies, not new time periods. Does NOT corroborate temporal generalisation.
A40: 3. NOMINALLY SIGNIFICANT, STILL UNDERPOWERED | B40: p=0.0244 clears 0.05 nominally; MDE=±19.5pp — the subset stays underpowered and the RECONSTRUCTED caveat above still applies, so treat as suggestive.

Sheet Accuracy_Conventions
A1: Accuracy Conventions — Coverage vs Selectivity
A2: Coverage accuracy = YES / all events (HOLDs counted as failures when stock moved, credited as correct when stock stayed flat). Selectivity accuracy = correct direction / (traded-and-graded events only: BUY or SELL call AND |ret_overnight| > 2%). Neither figure travels alone: selectivity inflates when the HOLD rate is high, because the model can selectively avoid hard calls. The FLAT convention gives the LLM an advantage in the paired comparison because the LLM holds 31.2% of events vs the human arm's 23.5% (N=170 paired subset): when the LLM holds and the stock stays flat, it earns a YES; a human BUY/SELL on the same event would earn a NO. See methodology_flat_convention.md for full derivation.
A3: CROSS-CHECK NOTE (figures below are at the SUPERSEDED 0.55/0.45 constants, which is what was investigated on 2026-08-13; at the deployed 0.80/0.20 the arm reads 68/109 = 62.4%): the selectivity formula (H=BUY/SELL, Q=UP/DOWN) gives 61/94 = 64.9% for the LLM arm. The repo authoritative figure is 62/95 = 65.3% (from item_e_walkforward.json, run 20260812_183842). Discrepancy = 1 event. Cause: one event's |ret_overnight| is below the ±2% band in the current returns_matrix but was apparently above it in the ext2 run. The formula definition is correct; the 0.4pp deviation is documented here.
A5: COVERAGE ACCURACY (YES / all events)
A6: Denominator: all events for the arm (including HOLDs) | F6: Floor: majority direction / all events
A7: Arm | B7: n (denom) | C7: YES | D7: Accuracy | E7: Floor n_DOWN | F7: Floor prob | G7: p-value (1-sided) | H7: MDE (±, 90%) | I7: HOLD count | J7: HOLD rate | K7: Traded
A8: LLM (DeepSeek) | B8: =COUNTIFS(LLM_Data_Entry!$F$3:$F$430,"LLM",LLM_Data_Entry!$R$3:$R$430,"<>") | C8: =COUNTIFS(LLM_Data_Entry!$F$3:$F$430,"LLM",LLM_Data_Entry!$R$3:$R$430,"YES") | D8: =IF(B8=0,"",C8/B8) | E8: =COUNTIFS(LLM_Data_Entry!$F$3:$F$430,"LLM",LLM_Data_Entry!$Q$3:$Q$430,"DOWN") | F8: =IF(B8=0,"",E8/B8) | G8: =IFERROR(1 - _xlfn.SINGLE(_xlfn.BINOM.DIST(C8 - 1, B8, F8, TRUE)), "") | H8: =IFERROR(2*1.645*SQRT(F8*(1-F8)/B8),"") | I8: =COUNTIFS(LLM_Data_Entry!$F$3:$F$430,"LLM",LLM_Data_Entry!$H$3:$H$430,"HOLD") | J8: =IFERROR(I8/(I8+K8),"") | K8: =COUNTIFS(LLM_Data_Entry!$F$3:$F$430,"LLM",LLM_Data_Entry!$H$3:$H$430,"BUY")+COUNTIFS(LLM_Data_Entry!$F$3:$F$430,"LLM",LLM_Data_Entry!$H$3:$H$430,"SELL")
A9: Human (All) | B9: =COUNTIF(Human_Data_Entry!$S$3:$S$524,"YES")+COUNTIF(Human_Data_Entry!$S$3:$S$524,"NO") | C9: =COUNTIF(Human_Data_Entry!$S$3:$S$524,"YES") | D9: =IF(B9=0,"",C9/B9) | E9: =COUNTIF(Human_Data_Entry!$R$3:$R$524,"DOWN") | F9: =IF(B9=0,"",E9/B9) | G9: =IFERROR(1 - _xlfn.SINGLE(_xlfn.BINOM.DIST(C9 - 1, B9, F9, TRUE)), "") | H9: =IFERROR(2*1.645*SQRT(F9*(1-F9)/B9),"") | I9: =COUNTIF(Human_Data_Entry!$J$3:$J$524,"HOLD") | J9: =IFERROR(I9/(I9+K9),"") | K9: =COUNTIF(Human_Data_Entry!$J$3:$J$524,"BUY")+COUNTIF(Human_Data_Entry!$J$3:$J$524,"SELL")
A10: =Settings!$A$8 | B10: =COUNTIFS(Human_Data_Entry!$G$3:$G$524,A10,Human_Data_Entry!$S$3:$S$524,"<>") | C10: =COUNTIFS(Human_Data_Entry!$G$3:$G$524,A10,Human_Data_Entry!$S$3:$S$524,"YES") | D10: =IF(B10=0,"",C10/B10) | E10: =COUNTIFS(Human_Data_Entry!$G$3:$G$524,A10,Human_Data_Entry!$R$3:$R$524,"DOWN") | F10: =IF(B10=0,"",E10/B10) | G10: =IFERROR(1 - _xlfn.SINGLE(_xlfn.BINOM.DIST(C10 - 1, B10, F10, TRUE)), "") | H10: =IFERROR(2*1.645*SQRT(F10*(1-F10)/B10),"") | I10: =COUNTIFS(Human_Data_Entry!$G$3:$G$524,A10,Human_Data_Entry!$J$3:$J$524,"HOLD") | J10: =IFERROR(I10/(I10+K10),"") | K10: =COUNTIFS(Human_Data_Entry!$G$3:$G$524,A10,Human_Data_Entry!$J$3:$J$524,"BUY")+COUNTIFS(Human_Data_Entry!$G$3:$G$524,A10,Human_Data_Entry!$J$3:$J$524,"SELL")
A11: =Settings!$A$9 | B11: =COUNTIFS(Human_Data_Entry!$G$3:$G$524,A11,Human_Data_Entry!$S$3:$S$524,"<>") | C11: =COUNTIFS(Human_Data_Entry!$G$3:$G$524,A11,Human_Data_Entry!$S$3:$S$524,"YES") | D11: =IF(B11=0,"",C11/B11) | E11: =COUNTIFS(Human_Data_Entry!$G$3:$G$524,A11,Human_Data_Entry!$R$3:$R$524,"DOWN") | F11: =IF(B11=0,"",E11/B11) | G11: =IFERROR(1 - _xlfn.SINGLE(_xlfn.BINOM.DIST(C11 - 1, B11, F11, TRUE)), "") | H11: =IFERROR(2*1.645*SQRT(F11*(1-F11)/B11),"") | I11: =COUNTIFS(Human_Data_Entry!$G$3:$G$524,A11,Human_Data_Entry!$J$3:$J$524,"HOLD") | J11: =IFERROR(I11/(I11+K11),"") | K11: =COUNTIFS(Human_Data_Entry!$G$3:$G$524,A11,Human_Data_Entry!$J$3:$J$524,"BUY")+COUNTIFS(Human_Data_Entry!$G$3:$G$524,A11,Human_Data_Entry!$J$3:$J$524,"SELL")
A12: =Settings!$A$10 | B12: =COUNTIFS(Human_Data_Entry!$G$3:$G$524,A12,Human_Data_Entry!$S$3:$S$524,"<>") | C12: =COUNTIFS(Human_Data_Entry!$G$3:$G$524,A12,Human_Data_Entry!$S$3:$S$524,"YES") | D12: =IF(B12=0,"",C12/B12) | E12: =COUNTIFS(Human_Data_Entry!$G$3:$G$524,A12,Human_Data_Entry!$R$3:$R$524,"DOWN") | F12: =IF(B12=0,"",E12/B12) | G12: =IFERROR(1 - _xlfn.SINGLE(_xlfn.BINOM.DIST(C12 - 1, B12, F12, TRUE)), "") | H12: =IFERROR(2*1.645*SQRT(F12*(1-F12)/B12),"") | I12: =COUNTIFS(Human_Data_Entry!$G$3:$G$524,A12,Human_Data_Entry!$J$3:$J$524,"HOLD") | J12: =IFERROR(I12/(I12+K12),"") | K12: =COUNTIFS(Human_Data_Entry!$G$3:$G$524,A12,Human_Data_Entry!$J$3:$J$524,"BUY")+COUNTIFS(Human_Data_Entry!$G$3:$G$524,A12,Human_Data_Entry!$J$3:$J$524,"SELL")
A13: =Settings!$A$11 | B13: =COUNTIFS(Human_Data_Entry!$G$3:$G$524,A13,Human_Data_Entry!$S$3:$S$524,"<>") | C13: =COUNTIFS(Human_Data_Entry!$G$3:$G$524,A13,Human_Data_Entry!$S$3:$S$524,"YES") | D13: =IF(B13=0,"",C13/B13) | E13: =COUNTIFS(Human_Data_Entry!$G$3:$G$524,A13,Human_Data_Entry!$R$3:$R$524,"DOWN") | F13: =IF(B13=0,"",E13/B13) | G13: =IFERROR(1 - _xlfn.SINGLE(_xlfn.BINOM.DIST(C13 - 1, B13, F13, TRUE)), "") | H13: =IFERROR(2*1.645*SQRT(F13*(1-F13)/B13),"") | I13: =COUNTIFS(Human_Data_Entry!$G$3:$G$524,A13,Human_Data_Entry!$J$3:$J$524,"HOLD") | J13: =IFERROR(I13/(I13+K13),"") | K13: =COUNTIFS(Human_Data_Entry!$G$3:$G$524,A13,Human_Data_Entry!$J$3:$J$524,"BUY")+COUNTIFS(Human_Data_Entry!$G$3:$G$524,A13,Human_Data_Entry!$J$3:$J$524,"SELL")
A14: =Settings!$A$12 | B14: =COUNTIFS(Human_Data_Entry!$G$3:$G$524,A14,Human_Data_Entry!$S$3:$S$524,"<>") | C14: =COUNTIFS(Human_Data_Entry!$G$3:$G$524,A14,Human_Data_Entry!$S$3:$S$524,"YES") | D14: =IF(B14=0,"",C14/B14) | E14: =COUNTIFS(Human_Data_Entry!$G$3:$G$524,A14,Human_Data_Entry!$R$3:$R$524,"DOWN") | F14: =IF(B14=0,"",E14/B14) | G14: =IFERROR(1 - _xlfn.SINGLE(_xlfn.BINOM.DIST(C14 - 1, B14, F14, TRUE)), "") | H14: =IFERROR(2*1.645*SQRT(F14*(1-F14)/B14),"") | I14: =COUNTIFS(Human_Data_Entry!$G$3:$G$524,A14,Human_Data_Entry!$J$3:$J$524,"HOLD") | J14: =IFERROR(I14/(I14+K14),"") | K14: =COUNTIFS(Human_Data_Entry!$G$3:$G$524,A14,Human_Data_Entry!$J$3:$J$524,"BUY")+COUNTIFS(Human_Data_Entry!$G$3:$G$524,A14,Human_Data_Entry!$J$3:$J$524,"SELL")
A15: =Settings!$A$13 | B15: =COUNTIFS(Human_Data_Entry!$G$3:$G$524,A15,Human_Data_Entry!$S$3:$S$524,"<>") | C15: =COUNTIFS(Human_Data_Entry!$G$3:$G$524,A15,Human_Data_Entry!$S$3:$S$524,"YES") | D15: =IF(B15=0,"",C15/B15) | E15: =COUNTIFS(Human_Data_Entry!$G$3:$G$524,A15,Human_Data_Entry!$R$3:$R$524,"DOWN") | F15: =IF(B15=0,"",E15/B15) | G15: =IFERROR(1 - _xlfn.SINGLE(_xlfn.BINOM.DIST(C15 - 1, B15, F15, TRUE)), "") | H15: =IFERROR(2*1.645*SQRT(F15*(1-F15)/B15),"") | I15: =COUNTIFS(Human_Data_Entry!$G$3:$G$524,A15,Human_Data_Entry!$J$3:$J$524,"HOLD") | J15: =IFERROR(I15/(I15+K15),"") | K15: =COUNTIFS(Human_Data_Entry!$G$3:$G$524,A15,Human_Data_Entry!$J$3:$J$524,"BUY")+COUNTIFS(Human_Data_Entry!$G$3:$G$524,A15,Human_Data_Entry!$J$3:$J$524,"SELL")
A16: =Settings!$A$14 | B16: =COUNTIFS(Human_Data_Entry!$G$3:$G$524,A16,Human_Data_Entry!$S$3:$S$524,"<>") | C16: =COUNTIFS(Human_Data_Entry!$G$3:$G$524,A16,Human_Data_Entry!$S$3:$S$524,"YES") | D16: =IF(B16=0,"",C16/B16) | E16: =COUNTIFS(Human_Data_Entry!$G$3:$G$524,A16,Human_Data_Entry!$R$3:$R$524,"DOWN") | F16: =IF(B16=0,"",E16/B16) | G16: =IFERROR(1 - _xlfn.SINGLE(_xlfn.BINOM.DIST(C16 - 1, B16, F16, TRUE)), "") | H16: =IFERROR(2*1.645*SQRT(F16*(1-F16)/B16),"") | I16: =COUNTIFS(Human_Data_Entry!$G$3:$G$524,A16,Human_Data_Entry!$J$3:$J$524,"HOLD") | J16: =IFERROR(I16/(I16+K16),"") | K16: =COUNTIFS(Human_Data_Entry!$G$3:$G$524,A16,Human_Data_Entry!$J$3:$J$524,"BUY")+COUNTIFS(Human_Data_Entry!$G$3:$G$524,A16,Human_Data_Entry!$J$3:$J$524,"SELL")
A18: SELECTIVITY ACCURACY (correct / traded-and-graded events)
A19: Denominator: events where arm committed (BUY/SELL) AND |ret_overnight| > 2% | F19: Floor: DOWN outcomes / graded denominator
A20: Arm | B20: n (denom) | C20: YES | D20: Accuracy | E20: Floor n_DOWN | F20: Floor prob | G20: p-value (1-sided) | H20: MDE (±, 90%) | I20: HOLD count | J20: HOLD rate | K20: Traded
A21: LLM (DeepSeek) | B21: =COUNTIFS(LLM_Data_Entry!$F$3:$F$430,"LLM",LLM_Data_Entry!$H$3:$H$430,"BUY",LLM_Data_Entry!$Q$3:$Q$430,"UP")+COUNTIFS(LLM_Data_Entry!$F$3:$F$430,"LLM",LLM_Data_Entry!$H$3:$H$430,"BUY",LLM_Data_Entry!$Q$3:$Q$430,"DOWN")+COUNTIFS(LLM_Data_Entry!$F$3:$F$430,"LLM",LLM_Data_Entry!$H$3:$H$430,"SELL",LLM_Data_Entry!$Q$3:$Q$430,"UP")+COUNTIFS(LLM_Data_Entry!$F$3:$F$430,"LLM",LLM_Data_Entry!$H$3:$H$430,"SELL",LLM_Data_Entry!$Q$3:$Q$430,"DOWN") | C21: =COUNTIFS(LLM_Data_Entry!$F$3:$F$430,"LLM",LLM_Data_Entry!$H$3:$H$430,"BUY",LLM_Data_Entry!$Q$3:$Q$430,"UP")+COUNTIFS(LLM_Data_Entry!$F$3:$F$430,"LLM",LLM_Data_Entry!$H$3:$H$430,"SELL",LLM_Data_Entry!$Q$3:$Q$430,"DOWN") | D21: =IF(B21=0,"",C21/B21) | E21: =COUNTIFS(LLM_Data_Entry!$F$3:$F$430,"LLM",LLM_Data_Entry!$H$3:$H$430,"BUY",LLM_Data_Entry!$Q$3:$Q$430,"DOWN")+COUNTIFS(LLM_Data_Entry!$F$3:$F$430,"LLM",LLM_Data_Entry!$H$3:$H$430,"SELL",LLM_Data_Entry!$Q$3:$Q$430,"DOWN") | F21: =IF(B21=0,"",E21/B21) | G21: =IFERROR(1 - _xlfn.SINGLE(_xlfn.BINOM.DIST(C21 - 1, B21, F21, TRUE)), "") | H21: =IFERROR(2*1.645*SQRT(F21*(1-F21)/B21),"") | I21: =COUNTIFS(LLM_Data_Entry!$F$3:$F$430,"LLM",LLM_Data_Entry!$H$3:$H$430,"HOLD") | J21: =IFERROR(I21/(I21+K21),"") | K21: =COUNTIFS(LLM_Data_Entry!$F$3:$F$430,"LLM",LLM_Data_Entry!$H$3:$H$430,"BUY")+COUNTIFS(LLM_Data_Entry!$F$3:$F$430,"LLM",LLM_Data_Entry!$H$3:$H$430,"SELL")
A22: Human (All) | B22: =COUNTIFS(Human_Data_Entry!$J$3:$J$524,"BUY",Human_Data_Entry!$R$3:$R$524,"UP")+COUNTIFS(Human_Data_Entry!$J$3:$J$524,"BUY",Human_Data_Entry!$R$3:$R$524,"DOWN")+COUNTIFS(Human_Data_Entry!$J$3:$J$524,"SELL",Human_Data_Entry!$R$3:$R$524,"UP")+COUNTIFS(Human_Data_Entry!$J$3:$J$524,"SELL",Human_Data_Entry!$R$3:$R$524,"DOWN") | C22: =COUNTIFS(Human_Data_Entry!$J$3:$J$524,"BUY",Human_Data_Entry!$R$3:$R$524,"UP")+COUNTIFS(Human_Data_Entry!$J$3:$J$524,"SELL",Human_Data_Entry!$R$3:$R$524,"DOWN") | D22: =IF(B22=0,"",C22/B22) | E22: =COUNTIFS(Human_Data_Entry!$J$3:$J$524,"BUY",Human_Data_Entry!$R$3:$R$524,"DOWN")+COUNTIFS(Human_Data_Entry!$J$3:$J$524,"SELL",Human_Data_Entry!$R$3:$R$524,"DOWN") | F22: =IF(B22=0,"",E22/B22) | G22: =IFERROR(1 - _xlfn.SINGLE(_xlfn.BINOM.DIST(C22 - 1, B22, F22, TRUE)), "") | H22: =IFERROR(2*1.645*SQRT(F22*(1-F22)/B22),"") | I22: =COUNTIF(Human_Data_Entry!$J$3:$J$524,"HOLD") | J22: =IFERROR(I22/(I22+K22),"") | K22: =COUNTIF(Human_Data_Entry!$J$3:$J$524,"BUY")+COUNTIF(Human_Data_Entry!$J$3:$J$524,"SELL")
A23: =Settings!$A$8 | B23: =COUNTIFS(Human_Data_Entry!$G$3:$G$524,A23,Human_Data_Entry!$J$3:$J$524,"BUY",Human_Data_Entry!$R$3:$R$524,"UP")+COUNTIFS(Human_Data_Entry!$G$3:$G$524,A23,Human_Data_Entry!$J$3:$J$524,"BUY",Human_Data_Entry!$R$3:$R$524,"DOWN")+COUNTIFS(Human_Data_Entry!$G$3:$G$524,A23,Human_Data_Entry!$J$3:$J$524,"SELL",Human_Data_Entry!$R$3:$R$524,"UP")+COUNTIFS(Human_Data_Entry!$G$3:$G$524,A23,Human_Data_Entry!$J$3:$J$524,"SELL",Human_Data_Entry!$R$3:$R$524,"DOWN") | C23: =COUNTIFS(Human_Data_Entry!$G$3:$G$524,A23,Human_Data_Entry!$J$3:$J$524,"BUY",Human_Data_Entry!$R$3:$R$524,"UP")+COUNTIFS(Human_Data_Entry!$G$3:$G$524,A23,Human_Data_Entry!$J$3:$J$524,"SELL",Human_Data_Entry!$R$3:$R$524,"DOWN") | D23: =IF(B23=0,"",C23/B23) | E23: =COUNTIFS(Human_Data_Entry!$G$3:$G$524,A23,Human_Data_Entry!$J$3:$J$524,"BUY",Human_Data_Entry!$R$3:$R$524,"DOWN")+COUNTIFS(Human_Data_Entry!$G$3:$G$524,A23,Human_Data_Entry!$J$3:$J$524,"SELL",Human_Data_Entry!$R$3:$R$524,"DOWN") | F23: =IF(B23=0,"",E23/B23) | G23: =IFERROR(1 - _xlfn.SINGLE(_xlfn.BINOM.DIST(C23 - 1, B23, F23, TRUE)), "") | H23: =IFERROR(2*1.645*SQRT(F23*(1-F23)/B23),"") | I23: =COUNTIFS(Human_Data_Entry!$G$3:$G$524,A23,Human_Data_Entry!$J$3:$J$524,"HOLD") | J23: =IFERROR(I23/(I23+K23),"") | K23: =COUNTIFS(Human_Data_Entry!$G$3:$G$524,A23,Human_Data_Entry!$J$3:$J$524,"BUY")+COUNTIFS(Human_Data_Entry!$G$3:$G$524,A23,Human_Data_Entry!$J$3:$J$524,"SELL")
A24: =Settings!$A$9 | B24: =COUNTIFS(Human_Data_Entry!$G$3:$G$524,A24,Human_Data_Entry!$J$3:$J$524,"BUY",Human_Data_Entry!$R$3:$R$524,"UP")+COUNTIFS(Human_Data_Entry!$G$3:$G$524,A24,Human_Data_Entry!$J$3:$J$524,"BUY",Human_Data_Entry!$R$3:$R$524,"DOWN")+COUNTIFS(Human_Data_Entry!$G$3:$G$524,A24,Human_Data_Entry!$J$3:$J$524,"SELL",Human_Data_Entry!$R$3:$R$524,"UP")+COUNTIFS(Human_Data_Entry!$G$3:$G$524,A24,Human_Data_Entry!$J$3:$J$524,"SELL",Human_Data_Entry!$R$3:$R$524,"DOWN") | C24: =COUNTIFS(Human_Data_Entry!$G$3:$G$524,A24,Human_Data_Entry!$J$3:$J$524,"BUY",Human_Data_Entry!$R$3:$R$524,"UP")+COUNTIFS(Human_Data_Entry!$G$3:$G$524,A24,Human_Data_Entry!$J$3:$J$524,"SELL",Human_Data_Entry!$R$3:$R$524,"DOWN") | D24: =IF(B24=0,"",C24/B24) | E24: =COUNTIFS(Human_Data_Entry!$G$3:$G$524,A24,Human_Data_Entry!$J$3:$J$524,"BUY",Human_Data_Entry!$R$3:$R$524,"DOWN")+COUNTIFS(Human_Data_Entry!$G$3:$G$524,A24,Human_Data_Entry!$J$3:$J$524,"SELL",Human_Data_Entry!$R$3:$R$524,"DOWN") | F24: =IF(B24=0,"",E24/B24) | G24: =IFERROR(1 - _xlfn.SINGLE(_xlfn.BINOM.DIST(C24 - 1, B24, F24, TRUE)), "") | H24: =IFERROR(2*1.645*SQRT(F24*(1-F24)/B24),"") | I24: =COUNTIFS(Human_Data_Entry!$G$3:$G$524,A24,Human_Data_Entry!$J$3:$J$524,"HOLD") | J24: =IFERROR(I24/(I24+K24),"") | K24: =COUNTIFS(Human_Data_Entry!$G$3:$G$524,A24,Human_Data_Entry!$J$3:$J$524,"BUY")+COUNTIFS(Human_Data_Entry!$G$3:$G$524,A24,Human_Data_Entry!$J$3:$J$524,"SELL")
A25: =Settings!$A$10 | B25: =COUNTIFS(Human_Data_Entry!$G$3:$G$524,A25,Human_Data_Entry!$J$3:$J$524,"BUY",Human_Data_Entry!$R$3:$R$524,"UP")+COUNTIFS(Human_Data_Entry!$G$3:$G$524,A25,Human_Data_Entry!$J$3:$J$524,"BUY",Human_Data_Entry!$R$3:$R$524,"DOWN")+COUNTIFS(Human_Data_Entry!$G$3:$G$524,A25,Human_Data_Entry!$J$3:$J$524,"SELL",Human_Data_Entry!$R$3:$R$524,"UP")+COUNTIFS(Human_Data_Entry!$G$3:$G$524,A25,Human_Data_Entry!$J$3:$J$524,"SELL",Human_Data_Entry!$R$3:$R$524,"DOWN") | C25: =COUNTIFS(Human_Data_Entry!$G$3:$G$524,A25,Human_Data_Entry!$J$3:$J$524,"BUY",Human_Data_Entry!$R$3:$R$524,"UP")+COUNTIFS(Human_Data_Entry!$G$3:$G$524,A25,Human_Data_Entry!$J$3:$J$524,"SELL",Human_Data_Entry!$R$3:$R$524,"DOWN") | D25: =IF(B25=0,"",C25/B25) | E25: =COUNTIFS(Human_Data_Entry!$G$3:$G$524,A25,Human_Data_Entry!$J$3:$J$524,"BUY",Human_Data_Entry!$R$3:$R$524,"DOWN")+COUNTIFS(Human_Data_Entry!$G$3:$G$524,A25,Human_Data_Entry!$J$3:$J$524,"SELL",Human_Data_Entry!$R$3:$R$524,"DOWN") | F25: =IF(B25=0,"",E25/B25) | G25: =IFERROR(1 - _xlfn.SINGLE(_xlfn.BINOM.DIST(C25 - 1, B25, F25, TRUE)), "") | H25: =IFERROR(2*1.645*SQRT(F25*(1-F25)/B25),"") | I25: =COUNTIFS(Human_Data_Entry!$G$3:$G$524,A25,Human_Data_Entry!$J$3:$J$524,"HOLD") | J25: =IFERROR(I25/(I25+K25),"") | K25: =COUNTIFS(Human_Data_Entry!$G$3:$G$524,A25,Human_Data_Entry!$J$3:$J$524,"BUY")+COUNTIFS(Human_Data_Entry!$G$3:$G$524,A25,Human_Data_Entry!$J$3:$J$524,"SELL")
A26: =Settings!$A$11 | B26: =COUNTIFS(Human_Data_Entry!$G$3:$G$524,A26,Human_Data_Entry!$J$3:$J$524,"BUY",Human_Data_Entry!$R$3:$R$524,"UP")+COUNTIFS(Human_Data_Entry!$G$3:$G$524,A26,Human_Data_Entry!$J$3:$J$524,"BUY",Human_Data_Entry!$R$3:$R$524,"DOWN")+COUNTIFS(Human_Data_Entry!$G$3:$G$524,A26,Human_Data_Entry!$J$3:$J$524,"SELL",Human_Data_Entry!$R$3:$R$524,"UP")+COUNTIFS(Human_Data_Entry!$G$3:$G$524,A26,Human_Data_Entry!$J$3:$J$524,"SELL",Human_Data_Entry!$R$3:$R$524,"DOWN") | C26: =COUNTIFS(Human_Data_Entry!$G$3:$G$524,A26,Human_Data_Entry!$J$3:$J$524,"BUY",Human_Data_Entry!$R$3:$R$524,"UP")+COUNTIFS(Human_Data_Entry!$G$3:$G$524,A26,Human_Data_Entry!$J$3:$J$524,"SELL",Human_Data_Entry!$R$3:$R$524,"DOWN") | D26: =IF(B26=0,"",C26/B26) | E26: =COUNTIFS(Human_Data_Entry!$G$3:$G$524,A26,Human_Data_Entry!$J$3:$J$524,"BUY",Human_Data_Entry!$R$3:$R$524,"DOWN")+COUNTIFS(Human_Data_Entry!$G$3:$G$524,A26,Human_Data_Entry!$J$3:$J$524,"SELL",Human_Data_Entry!$R$3:$R$524,"DOWN") | F26: =IF(B26=0,"",E26/B26) | G26: =IFERROR(1 - _xlfn.SINGLE(_xlfn.BINOM.DIST(C26 - 1, B26, F26, TRUE)), "") | H26: =IFERROR(2*1.645*SQRT(F26*(1-F26)/B26),"") | I26: =COUNTIFS(Human_Data_Entry!$G$3:$G$524,A26,Human_Data_Entry!$J$3:$J$524,"HOLD") | J26: =IFERROR(I26/(I26+K26),"") | K26: =COUNTIFS(Human_Data_Entry!$G$3:$G$524,A26,Human_Data_Entry!$J$3:$J$524,"BUY")+COUNTIFS(Human_Data_Entry!$G$3:$G$524,A26,Human_Data_Entry!$J$3:$J$524,"SELL")
A27: =Settings!$A$12 | B27: =COUNTIFS(Human_Data_Entry!$G$3:$G$524,A27,Human_Data_Entry!$J$3:$J$524,"BUY",Human_Data_Entry!$R$3:$R$524,"UP")+COUNTIFS(Human_Data_Entry!$G$3:$G$524,A27,Human_Data_Entry!$J$3:$J$524,"BUY",Human_Data_Entry!$R$3:$R$524,"DOWN")+COUNTIFS(Human_Data_Entry!$G$3:$G$524,A27,Human_Data_Entry!$J$3:$J$524,"SELL",Human_Data_Entry!$R$3:$R$524,"UP")+COUNTIFS(Human_Data_Entry!$G$3:$G$524,A27,Human_Data_Entry!$J$3:$J$524,"SELL",Human_Data_Entry!$R$3:$R$524,"DOWN") | C27: =COUNTIFS(Human_Data_Entry!$G$3:$G$524,A27,Human_Data_Entry!$J$3:$J$524,"BUY",Human_Data_Entry!$R$3:$R$524,"UP")+COUNTIFS(Human_Data_Entry!$G$3:$G$524,A27,Human_Data_Entry!$J$3:$J$524,"SELL",Human_Data_Entry!$R$3:$R$524,"DOWN") | D27: =IF(B27=0,"",C27/B27) | E27: =COUNTIFS(Human_Data_Entry!$G$3:$G$524,A27,Human_Data_Entry!$J$3:$J$524,"BUY",Human_Data_Entry!$R$3:$R$524,"DOWN")+COUNTIFS(Human_Data_Entry!$G$3:$G$524,A27,Human_Data_Entry!$J$3:$J$524,"SELL",Human_Data_Entry!$R$3:$R$524,"DOWN") | F27: =IF(B27=0,"",E27/B27) | G27: =IFERROR(1 - _xlfn.SINGLE(_xlfn.BINOM.DIST(C27 - 1, B27, F27, TRUE)), "") | H27: =IFERROR(2*1.645*SQRT(F27*(1-F27)/B27),"") | I27: =COUNTIFS(Human_Data_Entry!$G$3:$G$524,A27,Human_Data_Entry!$J$3:$J$524,"HOLD") | J27: =IFERROR(I27/(I27+K27),"") | K27: =COUNTIFS(Human_Data_Entry!$G$3:$G$524,A27,Human_Data_Entry!$J$3:$J$524,"BUY")+COUNTIFS(Human_Data_Entry!$G$3:$G$524,A27,Human_Data_Entry!$J$3:$J$524,"SELL")
A28: =Settings!$A$13 | B28: =COUNTIFS(Human_Data_Entry!$G$3:$G$524,A28,Human_Data_Entry!$J$3:$J$524,"BUY",Human_Data_Entry!$R$3:$R$524,"UP")+COUNTIFS(Human_Data_Entry!$G$3:$G$524,A28,Human_Data_Entry!$J$3:$J$524,"BUY",Human_Data_Entry!$R$3:$R$524,"DOWN")+COUNTIFS(Human_Data_Entry!$G$3:$G$524,A28,Human_Data_Entry!$J$3:$J$524,"SELL",Human_Data_Entry!$R$3:$R$524,"UP")+COUNTIFS(Human_Data_Entry!$G$3:$G$524,A28,Human_Data_Entry!$J$3:$J$524,"SELL",Human_Data_Entry!$R$3:$R$524,"DOWN") | C28: =COUNTIFS(Human_Data_Entry!$G$3:$G$524,A28,Human_Data_Entry!$J$3:$J$524,"BUY",Human_Data_Entry!$R$3:$R$524,"UP")+COUNTIFS(Human_Data_Entry!$G$3:$G$524,A28,Human_Data_Entry!$J$3:$J$524,"SELL",Human_Data_Entry!$R$3:$R$524,"DOWN") | D28: =IF(B28=0,"",C28/B28) | E28: =COUNTIFS(Human_Data_Entry!$G$3:$G$524,A28,Human_Data_Entry!$J$3:$J$524,"BUY",Human_Data_Entry!$R$3:$R$524,"DOWN")+COUNTIFS(Human_Data_Entry!$G$3:$G$524,A28,Human_Data_Entry!$J$3:$J$524,"SELL",Human_Data_Entry!$R$3:$R$524,"DOWN") | F28: =IF(B28=0,"",E28/B28) | G28: =IFERROR(1 - _xlfn.SINGLE(_xlfn.BINOM.DIST(C28 - 1, B28, F28, TRUE)), "") | H28: =IFERROR(2*1.645*SQRT(F28*(1-F28)/B28),"") | I28: =COUNTIFS(Human_Data_Entry!$G$3:$G$524,A28,Human_Data_Entry!$J$3:$J$524,"HOLD") | J28: =IFERROR(I28/(I28+K28),"") | K28: =COUNTIFS(Human_Data_Entry!$G$3:$G$524,A28,Human_Data_Entry!$J$3:$J$524,"BUY")+COUNTIFS(Human_Data_Entry!$G$3:$G$524,A28,Human_Data_Entry!$J$3:$J$524,"SELL")
A29: =Settings!$A$14 | B29: =COUNTIFS(Human_Data_Entry!$G$3:$G$524,A29,Human_Data_Entry!$J$3:$J$524,"BUY",Human_Data_Entry!$R$3:$R$524,"UP")+COUNTIFS(Human_Data_Entry!$G$3:$G$524,A29,Human_Data_Entry!$J$3:$J$524,"BUY",Human_Data_Entry!$R$3:$R$524,"DOWN")+COUNTIFS(Human_Data_Entry!$G$3:$G$524,A29,Human_Data_Entry!$J$3:$J$524,"SELL",Human_Data_Entry!$R$3:$R$524,"UP")+COUNTIFS(Human_Data_Entry!$G$3:$G$524,A29,Human_Data_Entry!$J$3:$J$524,"SELL",Human_Data_Entry!$R$3:$R$524,"DOWN") | C29: =COUNTIFS(Human_Data_Entry!$G$3:$G$524,A29,Human_Data_Entry!$J$3:$J$524,"BUY",Human_Data_Entry!$R$3:$R$524,"UP")+COUNTIFS(Human_Data_Entry!$G$3:$G$524,A29,Human_Data_Entry!$J$3:$J$524,"SELL",Human_Data_Entry!$R$3:$R$524,"DOWN") | D29: =IF(B29=0,"",C29/B29) | E29: =COUNTIFS(Human_Data_Entry!$G$3:$G$524,A29,Human_Data_Entry!$J$3:$J$524,"BUY",Human_Data_Entry!$R$3:$R$524,"DOWN")+COUNTIFS(Human_Data_Entry!$G$3:$G$524,A29,Human_Data_Entry!$J$3:$J$524,"SELL",Human_Data_Entry!$R$3:$R$524,"DOWN") | F29: =IF(B29=0,"",E29/B29) | G29: =IFERROR(1 - _xlfn.SINGLE(_xlfn.BINOM.DIST(C29 - 1, B29, F29, TRUE)), "") | H29: =IFERROR(2*1.645*SQRT(F29*(1-F29)/B29),"") | I29: =COUNTIFS(Human_Data_Entry!$G$3:$G$524,A29,Human_Data_Entry!$J$3:$J$524,"HOLD") | J29: =IFERROR(I29/(I29+K29),"") | K29: =COUNTIFS(Human_Data_Entry!$G$3:$G$524,A29,Human_Data_Entry!$J$3:$J$524,"BUY")+COUNTIFS(Human_Data_Entry!$G$3:$G$524,A29,Human_Data_Entry!$J$3:$J$524,"SELL")
A30: CHART NOTE: The two floor-level series ('Coverage floor' and 'Selectivity floor') are rendered as bars, not horizontal lines, because openpyxl cannot produce a clean bar+line combo chart without raw XML manipulation. To convert to horizontal lines: open in Excel → right-click each floor series → Change Series Chart Type → Line. The coverage and selectivity bars show accuracy; floor bars show the naive majority-direction baseline for the matching denominator.
A31: Chart data (feeds accuracy comparison chart below)
A32: Arm | B32: Coverage acc | C32: Selectivity acc | D32: Coverage floor | E32: Selectivity floor
A33: LLM | B33: =D8 | C33: =D21 | D33: =F8 | E33: =F21
A34: Human (All) | B34: =D9 | C34: =D22 | D34: =F9 | E34: =F22
A60: KEY DISTINCTION: Coverage (47%) and selectivity (62%) are not both correct — they measure different things on different denominators. Coverage penalises every HOLD call; selectivity credits only committed events that moved. Quoting one without the other is misleading. The repo's headline accuracy figure is selectivity (68/109 = 62.4%, from item_e_walkforward.json); the workbook Summary and Figure 1 show coverage (47% for LLM). Both are real; neither is the whole story.
A63: RECORD (2026-08-13 basis, derived 2026-08-21) — Human arm, the 295 rows then marked Price Basis Corrected = YES. The cells in rows 66–74 were live COUNTIFS formulas that silently tracked the BS column as it grew to 405, so the earlier claim here that the figures had 'NOT been re-run' was wrong — and no 295-era values were ever frozen in any committed vintage. The human values below are now typed records derived from the committed 2026-08-13 workbook vintage (raw prices and scores, same formula semantics). Current 405-row tables: rows 94–101. Ledger L9.
A64: Human cells below are typed record values (2026-08-13 basis, 295 corrected rows, original-price correctness). LLM cells remain live single-basis formulas — their inputs did not change. For current human figures use rows 94–101; comparing the two shows the effect of the re-anchoring completed since.
A66: Coverage (2026-08-13 record: 295 corrected rows)
A67: Arm | B67: YES | C67: N | D67: Accuracy | E67: Floor (always-DOWN) | F67: p-value | G67: MDE
A68: Human (all raters, 295 corrected) | B68: 106 | C68: 295 | D68: 0.3593 | E68: 0.3695 | F68: 0.6619 | G68: =IFERROR(2*1.645*SQRT(E68*(1-E68)/C68),"")
A69: LLM (single basis, unchanged) | B69: =COUNTIFS(LLM_Data_Entry!$F$3:$F$430,"LLM",LLM_Data_Entry!$R$3:$R$430,"YES") | C69: =COUNTIFS(LLM_Data_Entry!$F$3:$F$430,"LLM",LLM_Data_Entry!$R$3:$R$430,"<>") | D69: =IFERROR(B69/C69,"") | E69: =IFERROR(COUNTIFS(LLM_Data_Entry!$F$3:$F$430,"LLM",LLM_Data_Entry!$Q$3:$Q$430,"DOWN")/COUNTIFS(LLM_Data_Entry!$F$3:$F$430,"LLM",LLM_Data_Entry!$R$3:$R$430,"<>"),"") | F69: =IFERROR(1 - _xlfn.SINGLE(_xlfn.BINOM.DIST(B69 - 1, C69, E69, TRUE)), "") | G69: =IFERROR(2*1.645*SQRT(E69*(1-E69)/C69),"")
A71: Selectivity (2026-08-13 record: 295 corrected rows)
...

Sheet Sector_Breakdown
A1: Set B is thin outside Technology (n_graded=15) and Consumer (n_graded=13). Energy, Utilities and Materials are below the n_graded<3 threshold and no accuracy is reported for them. Do not compare Set B sector accuracy against Set A without noting the sample-size difference.
A3: sector | B3: event_set | C3: n_events | D3: n_graded | E3: n_correct_coverage | F3: accuracy_coverage | G3: notes
A4: Technology | B4: Set A — N=232 frozen | C4: 36 | D4: 31 | E4: 13 | F4: 0.419 | G4: "Includes AAPL AVGO DELL IBM LNVGY MU MSFT ORCL PLTR UBER WDAY (broad Technology grouping)"
A5: Consumer | B5: Set A — N=232 frozen | C5: 86 | D5: 49 | E5: 23 | F5: 0.469 | G5: "Largest sector by N. Includes ABNB BKNG CMG COST CL EXPE F GIS HLT KHC KO LOW LULU MAR MCD NKE PEP PUM.DE RMSP.XC SBUX TGT TSLA WMT etc."
A6: Financials | B6: Set A — N=232 frozen | C6: 49 | D6: 22 | E6: 9 | F6: 0.409 | G6: "Includes BAC BCS C COIN GS HOOD JPM MET PYPL SCHW STAN.L V AXP ALV.DE"
A7: Industrials | B7: Set A — N=232 frozen | C7: 26 | D7: 17 | E7: 9 | F7: 0.529 | G7: "Includes AMKBY BA CAT DAL FDX LMT SIE.DE UAL"
A8: Communication Services | B8: Set A — N=232 frozen | C8: 18 | D8: 17 | E8: 7 | F8: 0.412 | G8: "Includes CMCSA DIS META NFLX PINS (note: META/NFLX worksheet-excluded pairs removed)"
A9: Healthcare | B9: Set A — N=232 frozen | C9: 14 | D9: 9 | E9: 7 | F9: 0.778 | G9: "Includes CVS JNJ NVO PFE UNH; n_graded=9 — interpret cautiously"
A10: Materials | B10: Set A — N=232 frozen | C10: 3 | D10: 0 | E10: 0 | F10: n<3 | G10: "LIN only in clean set; 0 graded events in ±2% band"
A11: Total | B11: Set A — N=232 frozen | C11: 232 | D11: 145 | E11: 68 | F11: =E11/D11 | G11: "Coverage accuracy: 68/145. Selectivity (HOLD-excluded | H11: n=109 graded+traded): 62.4% (68/109)."
A12: Technology | B12: Set B — N=93 extension | C12: 18 | D12: 15 | E12: 8 | F12: 53.3% | G12: "ADBE DDOG INTC SHOP SONY; n_graded=15 — largest graded count in Set B"
A13: Consumer | B13: Set B — N=93 extension | C13: 26 | D13: 13 | E13: 1 | F13: 7.7% | G13: "CL COST EBAY HD HEIA.AS NSRGY RMSP.XC; n_graded=13"
A14: Utilities | B14: Set B — N=93 extension | C14: 13 | D14: 1 | E14: 1 | F14: n<3 | G14: "DUK only (13 events); DUK_FQ2_2025 graded after the 8-K acceptance-time dateline correction"
A15: Energy | B15: Set B — N=93 extension | C15: 21 | D15: 1 | E15: 1 | F15: n<3 | G15: "CVX XOM SHEL; only 1 graded event in ±2% band"
A16: Financials | B16: Set B — N=93 extension | C16: 8 | D16: 2 | E16: 1 | F16: n<3 | G16: "AXP MA; only 2 graded events — not reportable"
A17: Materials | B17: Set B — N=93 extension | C17: 3 | D17: 2 | E17: 1 | F17: n<3 | G17: "FCX; only 2 graded events — not reportable"
A18: Industrials | B18: Set B — N=93 extension | C18: 4 | D18: 0 | E18: 0 | F18: — | G18: "UNP; 0 graded events"
A19: Total | B19: Set B — N=93 extension | C19: 93 | D19: 34 | E19: 13 | F19: =E19/D19 | G19: "Coverage accuracy: 13/34. Selectivity (HOLD-excluded, n=18 graded+traded): 72.2% (13/18). Extension is pure eval."
A20: Technology | B20: Set C — N=325 combined | C20: 54 | D20: 46 | E20: 21 | F20: 45.7% | G20: "Set A (36/31/13) + Set B (18/15/8)"
A21: Consumer | B21: Set C — N=325 combined | C21: 112 | D21: 62 | E21: 24 | F21: 38.7% | G21: "Set A (86/49/23) + Set B (26/13/1)"
A22: Financials | B22: Set C — N=325 combined | C22: 57 | D22: 24 | E22: 10 | F22: 41.7% | G22: "Set A (49/22/9) + Set B (8/2/1)"
A23: Industrials | B23: Set C — N=325 combined | C23: 30 | D23: 17 | E23: 9 | F23: 52.9% | G23: "Set A (26/17/9) + Set B (4/0/0)"
A24: Communication Services | B24: Set C — N=325 combined | C24: 18 | D24: 17 | E24: 7 | F24: 41.2% | G24: "Set A only (18/17/7); no Set B events in this sector"
A25: Healthcare | B25: Set C — N=325 combined | C25: 14 | D25: 9 | E25: 7 | F25: 77.8% | G25: "Set A only (14/9/7); n_graded=9 — interpret cautiously"
A26: Energy | B26: Set C — N=325 combined | C26: 21 | D26: 1 | E26: 1 | F26: n<3 | G26: "Set B only (21/1/1)"
A27: Utilities | B27: Set C — N=325 combined | C27: 13 | D27: 1 | E27: 1 | F27: n<3 | G27: "Set B only (13/1/1)"
A28: Materials | B28: Set C — N=325 combined | C28: 6 | D28: 2 | E28: 1 | F28: n<3 | G28: "Set A (3/0/0) + Set B (3/2/1)"
A29: Total | B29: Set C — N=325 combined | C29: 325 | D29: 179 | E29: 81 | F29: =E29/D29 | G29: "Coverage accuracy: 81/179. In-sample walk-forward accuracy on graded+traded: 63.8% (81/127, deployed thresholds)."
A31: Set B is thin outside Technology (n_graded=15) and Consumer (n_graded=13). Energy, Utilities and Materials fall below the n_graded<3 threshold and no accuracy is reported for them. The counts themselves are the finding: the extension broadened sector coverage but the low-volatility sectors it added rarely breach the ±2% band, so they contribute coverage rather than graded events.
A34: A fuller sector analysis across four cuts — Spearman rank correlation, calibration of mean score against
A35: mean realised return, score dispersion against hold rate, and BUY versus SELL asymmetry — is in
A36: outputs/global/summary/sector_analysis_2026-08-15.md and its accompanying CSV. The signal is positive in
A37: every estimable sector rather than concentrated in one. Only four sectors in the frozen set carry enough
A38: events for both a correlation and a directional estimate, and most cells fall below the reporting
A39: threshold. Note that the fuller analysis uses the SECTORS dict as its canonical taxonomy, which classifies
A40: four CVS Health events as Healthcare where this tab places them in Consumer; both sum to 232; under the
A41: canonical taxonomy Healthcare reads 18/12/9 (75.0%) and Consumer 82/46/21 (45.7%) against this tab's 14/9/7 (77.8%) and 86/49/23 (46.9%).

Sheet Corrected_Metrics
A1: metric_name | B1: value | C1: unit | D1: n | E1: denominator_definition | F1: event_set | G1: convention | H1: ci_low | I1: ci_high | J1: ci_level | K1: p_value | L1: mde | M1: test_used | N1: threshold_dependent | O1: source_file | P1: notes
A2: total_events_scored | B2: 268 | C2: events | D2: 268 | F2: N=268 phase2 scored events | N2: FALSE | O2: effective_sample_funnel.md
A3: excluded_worksheet | B3: 25 | C3: events | D3: 268 | F3: N=268 | N3: FALSE | O3: worksheet_leak_flags.csv | P3: LLM input included human rater worksheet
A4: excluded_bad_document | B4: 2 | C4: events | N4: FALSE | O4: effective_sample_funnel.md | P4: SPOT_FQ1_2026 misattribution; DIS_FQ1_2025 look-ahead (excluded 2026-08-24)
A5: excluded_timing | B5: 9 | C5: events | N5: FALSE | O5: effective_sample_funnel.md | P5: 9 non-US issuers, timing unresolved
A6: clean_universe | B6: 232 | C6: events | F6: N=232 clean universe | N6: FALSE | O6: effective_sample_funnel.md
A7: traded_events | B7: 168 | C7: events | E7: Model called BUY or SELL | F7: N=232 clean universe | N7: TRUE | O7: ext2_holding_curve.csv
