Workbook
Name CompanyList: Company_List!$A$3:$A$207
Name DecisionList: Settings!$D$8:$D$10
Name DocumentList: Settings!$I$8:$I$12
Name QuarterList: Settings!$G$8:$G$12
Name RaterList: Settings!$A$8:$A$14
Name SectionList: Settings!$H$8:$H$11
Name TickerList: Company_List!$B$3:$B$207
Name YearList: Settings!$F$8:$F$14

Sheet Human_Data_Entry
A1: HUMAN ARM CORRECTED. Prices M to P re-anchored on release_date from EDGAR filing dates, 2026-08-13. 295 of 420 rows re-anchored; 125 remain on original report_date basis (human-only events not in LLM universe — see column 'Price Basis Corrected'). Columns Q to U and the Summary, Charts and Efficiency sheets recalculate from these. Original basis retained in Master_Data_LOCKED_2026-08-13.xlsx. See Corrections_Log. | W1: Derived from Time (mins). Do not type here. | X1: HELPER KEY | DO NOT EDIT HERE | AB1: SECTION C — re-priced on the declared basis. Values, not formulas. Nothing to the left of here has been changed. | AL1: SECTION D - provenance and classification. Phase is looked up from Company_List column G. Source File is blank where no document matched the event both uniquely and strongly enough to cite, and Source Basis says which. Nothing to the left of here was changed.
A2: Company | B2: Ticker | C2: Year | D2: Quarter | E2: Document | F2: Section | G2: Rater | H2: Type (Human/LLM) | I2: Sentiment Score (−1 to +1) | J2: Decision (BUY/HOLD/SELL) | K2: Time (mins) | L2: Document Date | M2: Prior Closing Date | N2: Prior Close ($) | O2: Next Opening Date | P2: Next Day Open ($) | Q2: Actual % Change | R2: Actual Direction | S2: Prediction Correct? | T2: Position | U2: Net P&L | V2: Notes / Risks Flagged | W2: Time (sec) | X2: Event Key | Y2: LLM Decision | Z2: LLM Correct? | AA2: Helper columns for the Efficiency sheet. Do not type here. | AB2: Re-priced basis | AC2: Re-priced listing | AD2: Re-priced prior close date | AE2: Re-priced prior close | AF2: Re-priced next open date | AG2: Re-priced next open | AH2: Re-priced % change | AI2: Re-priced direction | AJ2: Re-priced correct? | AK2: Re-priced net P&L | AL2: Phase | AM2: Source File | AN2: Source URL | AO2: Source Basis | AP2: In LLM Universe | AQ2: First Rater for Event | AR2: In Window | AS2: Information Set | AT2: Net P&L on trades (helper) | AU2: Net P&L on trades, re-priced (helper) | AV2: Conviction weight (helper) | AW2: Conviction-weighted P&L (helper) | AX2: Conviction weight, re-priced (helper) | AY2: Event Set | AZ2: Sector | BA2: Pass | BB2: Passes Recorded | BC2: First Reading for Rater-Event | BD2: Pass 1 Minutes | BE2: Pass 2 Minutes | BF2: Pass 1 Score | BG2: Peeked | BH2: AI Declared | BI2: Expectation (written before reading) | BJ2: Rater Record | BK2: Decisions Agree | BL2: Peeked - Basis | BM2: Source Documents Cited | BN2: Source Publisher | BO2: Source Licence Class | BP2: Source Is SEC Periodic Filing | BQ2: Source In Provenance Manifest | BR2: Document Date - Basis | BS2: Price Basis Corrected | BT2: Not Corrected Reason
A3: Netflix | B3: =IF(A3="","",_xlfn.XLOOKUP(A3, Company_List!$A:$A, Company_List!$B:$B, "")) -> NFLX | C3: 2026 | D3: Q1 | E3: All | F3: All | G3: Anna | H3: Human | I3: 0.5 | J3: =IF(OR(I3="",Settings!$B$6=""),"",IF(I3>Settings!$B$6,"BUY",IF(I3<-Settings!$B$6,"SELL","HOLD"))) -> BUY | K3: 38 | L3: 46128 | M3: 46128 | N3: 107.79 | O3: 46129 | P3: 96.37 | Q3: =IF(OR(N3="",P3=""),"",ROUND((P3-N3)/N3,4)) -> -0.1059 | R3: =IF(OR(N3="",P3=""),"",IF(Q3>Settings!$B$3/100,"UP",IF(Q3<-Settings!$B$3/100,"DOWN","FLAT"))) -> DOWN | S3: =IF(OR(N3="",P3="",J3=""),"",IF(OR(AND(J3="BUY",R3="UP"),AND(J3="SELL",R3="DOWN"),AND(J3="HOLD",R3="FLAT")),"YES","NO")) -> NO | T3: =IF(J3="","",IF(J3="BUY",1,IF(J3="SELL",-1,0))) -> 1 | U3: =IFERROR(IF(OR(J3="",N3="",P3=""),"",IF(T3=0,0,T3*Q3-Settings!$B$4/10000-IF(T3<0,Settings!$B$5/10000,0))),"") -> -0.1069 | W3: =IF($K3="","",$K3*60) -> 2280 | X3: =IF($A3="","",$A3&"|"&$C3&"|"&$D3) -> Netflix|2026|Q1 | Y3: =IFERROR(IF($X3="","",INDEX(LLM_Data_Entry!$H$3:$H$548,MATCH($X3,INDEX(LLM_Data_Entry!$A$3:$A$548&"|"&LLM_Data_Entry!$C$3:$C$548&"|"&LLM_Data_Entry!$D$3:$D$548,0),0))),"") -> SELL | Z3: =IFERROR(IF($X3="","",INDEX(LLM_Data_Entry!$R$3:$R$548,MATCH($X3,INDEX(LLM_Data_Entry!$A$3:$A$548&"|"&LLM_Data_Entry!$C$3:$C$548&"|"&LLM_Data_Entry!$D$3:$D$548,0),0))),"") -> YES | AB3: price signal — only this window shows an abnormal move | AC3: NFLX | AD3: 2026-04-16 | AE3: 107.79 | AF3: 2026-04-17 | AG3: 96.37 | AH3: -0.10594673 | AI3: DOWN | AJ3: NO | AK3: -0.106947 | AL3: =IF($A3="","",IFERROR(INDEX(Company_List!$G$3:$G$207,MATCH($A3,Company_List!$A$3:$A$207,0)),"unassigned")) -> P2 | AM3: Phase 2/Netflix/Netflix-Inc-_Earnings-Call_2026-04-16T00_00_00_English-1.pdf | AO3: unique filename match | AP3: =IF($A3="","",IF(COUNTIFS(LLM_Data_Entry!$A$3:$A$548,$A3)>0,"YES","NO")) -> YES | AQ3: =IF($A3="","",IF(COUNTIFS($A$3:$A3,$A3,$C$3:$C3,$C3,$D$3:$D3,$D3)=1,"YES","NO")) -> YES | AR3: =IF($A3="","",IF(AND($C3&"-"&$D3>=Settings!$B$19,$C3&"-"&$D3<=Settings!$B$20),"IN","OUT")) -> IN | AS3: =IF($A3="","",IF($F3="Financial Results","financials",IF($F3="Outlook/Guidance","guidance",IF($F3="Transcript Q&A","qanda",IF($F3="","unrecorded",IF($E3="All","full",IF($E3="","unrecorded",LOWER($E3)&" only"))))))) -> full | AT3: =IF(AND(OR($J3="BUY",$J3="SELL"),ISNUMBER($U3)),$U3,"") -> -0.1069 | AU3: =IF(AND(OR($J3="BUY",$J3="SELL"),ISNUMBER($AK3)),$AK3,"") -> -0.106947 | AV3: =IF(ISNUMBER($AT3),ABS(IF(ISNUMBER($I3),$I3,0)-Settings!$B$24),"") -> 0.5 | AW3: =IF(ISNUMBER($AV3),$AV3*$AT3,"") -> -0.05345 | AX3: =IF(ISNUMBER($AU3),ABS(IF(ISNUMBER($I3),$I3,0)-Settings!$B$24),"") -> 0.5 | AY3: FROZEN | AZ3: =IF($A3="","",IFERROR(INDEX(Company_List!$H$3:$H$207,MATCH($A3,Company_List!$A$3:$A$207,0)),"unassigned")) -> Communication Services | BC3: =IF($A3="","",IF(COUNTIFS($A$3:$A3,$A3,$C$3:$C3,$C3,$D$3:$D3,$D3,$G$3:$G3,$G3)=1,1,0)) -> 1 | BG3: no | BK3: =IF(OR($H3<>"Human",$S3="",$J3="",$Y3="",$Z3=""),"",IF(EXACT(UPPER($J3),UPPER($Y3)),1,0)) -> 0 | BL3: assumed - no rater record | BM3: 1 | BN3: S&P Global Market Intelligence (Capital IQ) | BO3: licensed vendor | BP3: no | BQ3: no | BS3: YES
A4: Netflix | B4: =IF(A4="","",_xlfn.XLOOKUP(A4, Company_List!$A:$A, Company_List!$B:$B, "")) -> NFLX | C4: 2025 | D4: Q2 | E4: All | F4: All | G4: Anna | H4: Human | I4: 0.2 | J4: =IF(OR(I4="",Settings!$B$6=""),"",IF(I4>Settings!$B$6,"BUY",IF(I4<-Settings!$B$6,"SELL","HOLD"))) -> HOLD | K4: 26 | L4: 45855 | M4: 45855 | N4: 127.417 | O4: 45856 | P4: 124.2 | Q4: =IF(OR(N4="",P4=""),"",ROUND((P4-N4)/N4,4)) -> -0.0252 | R4: =IF(OR(N4="",P4=""),"",IF(Q4>Settings!$B$3/100,"UP",IF(Q4<-Settings!$B$3/100,"DOWN","FLAT"))) -> DOWN | S4: =IF(OR(N4="",P4="",J4=""),"",IF(OR(AND(J4="BUY",R4="UP"),AND(J4="SELL",R4="DOWN"),AND(J4="HOLD",R4="FLAT")),"YES","NO")) -> NO | T4: =IF(J4="","",IF(J4="BUY",1,IF(J4="SELL",-1,0))) -> 0 | U4: =IFERROR(IF(OR(J4="",N4="",P4=""),"",IF(T4=0,0,T4*Q4-Settings!$B$4/10000-IF(T4<0,Settings!$B$5/10000,0))),"") -> 0 | W4: =IF($K4="","",$K4*60) -> 1560 | X4: =IF($A4="","",$A4&"|"&$C4&"|"&$D4) -> Netflix|2025|Q2 | Y4: =IFERROR(IF($X4="","",INDEX(LLM_Data_Entry!$H$3:$H$548,MATCH($X4,INDEX(LLM_Data_Entry!$A$3:$A$548&"|"&LLM_Data_Entry!$C$3:$C$548&"|"&LLM_Data_Entry!$D$3:$D$548,0),0))),"") -> HOLD | Z4: =IFERROR(IF($X4="","",INDEX(LLM_Data_Entry!$R$3:$R$548,MATCH($X4,INDEX(LLM_Data_Entry!$A$3:$A$548&"|"&LLM_Data_Entry!$C$3:$C$548&"|"&LLM_Data_Entry!$D$3:$D$548,0),0))),"") -> NO | AB4: price signal — only this window shows an abnormal move | AC4: NFLX | AD4: 2025-07-17 | AE4: 127.417 | AF4: 2025-07-18 | AG4: 124.196 | AH4: -0.025279209 | AI4: DOWN | AJ4: NO | AK4: 0 | AL4: =IF($A4="","",IFERROR(INDEX(Company_List!$G$3:$G$207,MATCH($A4,Company_List!$A$3:$A$207,0)),"unassigned")) -> P2 | AM4: Phase 2/Netflix/2025-Q2/NFLX-2025-Q2-press-release-SEC-EX-99-1.htm | AN4: https://www.sec.gov/Archives/edgar/data/1065280/000106528025000322/ex991_q225.htm | AO4: manifest | AP4: =IF($A4="","",IF(COUNTIFS(LLM_Data_Entry!$A$3:$A$548,$A4)>0,"YES","NO")) -> YES | AQ4: =IF($A4="","",IF(COUNTIFS($A$3:$A4,$A4,$C$3:$C4,$C4,$D$3:$D4,$D4)=1,"YES","NO")) -> YES | AR4: =IF($A4="","",IF(AND($C4&"-"&$D4>=Settings!$B$19,$C4&"-"&$D4<=Settings!$B$20),"IN","OUT")) -> IN | AS4: =IF($A4="","",IF($F4="Financial Results","financials",IF($F4="Outlook/Guidance","guidance",IF($F4="Transcript Q&A","qanda",IF($F4="","unrecorded",IF($E4="All","full",IF($E4="","unrecorded",LOWER($E4)&" only"))))))) -> full | AT4: =IF(AND(OR($J4="BUY",$J4="SELL"),ISNUMBER($U4)),$U4,"") | AU4: =IF(AND(OR($J4="BUY",$J4="SELL"),ISNUMBER($AK4)),$AK4,"") | AV4: =IF(ISNUMBER($AT4),ABS(IF(ISNUMBER($I4),$I4,0)-Settings!$B$24),"") | AW4: =IF(ISNUMBER($AV4),$AV4*$AT4,"") | AX4: =IF(ISNUMBER($AU4),ABS(IF(ISNUMBER($I4),$I4,0)-Settings!$B$24),"") | AY4: FROZEN | AZ4: =IF($A4="","",IFERROR(INDEX(Company_List!$H$3:$H$207,MATCH($A4,Company_List!$A$3:$A$207,0)),"unassigned")) -> Communication Services | BC4: =IF($A4="","",IF(COUNTIFS($A$3:$A4,$A4,$C$3:$C4,$C4,$D$3:$D4,$D4,$G$3:$G4,$G4)=1,1,0)) -> 1 | BG4: no | BK4: =IF(OR($H4<>"Human",$S4="",$J4="",$Y4="",$Z4=""),"",IF(EXACT(UPPER($J4),UPPER($Y4)),1,0)) -> 1 | BL4: assumed - no rater record | BM4: 1 | BN4: not publisher-identified | BO4: not publisher-identified | BP4: no | BQ4: yes | BS4: YES
A5: Netflix | B5: =IF(A5="","",_xlfn.XLOOKUP(A5, Company_List!$A:$A, Company_List!$B:$B, "")) -> NFLX | C5: 2025 | D5: Q3 | E5: All | F5: All | G5: Anna | H5: Human | I5: -0.2 | J5: =IF(OR(I5="",Settings!$B$6=""),"",IF(I5>Settings!$B$6,"BUY",IF(I5<-Settings!$B$6,"SELL","HOLD"))) -> HOLD | K5: 24 | L5: 45951 | M5: 45951 | N5: 124.135 | O5: 45952 | P5: 114.29 | Q5: =IF(OR(N5="",P5=""),"",ROUND((P5-N5)/N5,4)) -> -0.0793 | R5: =IF(OR(N5="",P5=""),"",IF(Q5>Settings!$B$3/100,"UP",IF(Q5<-Settings!$B$3/100,"DOWN","FLAT"))) -> DOWN | S5: =IF(OR(N5="",P5="",J5=""),"",IF(OR(AND(J5="BUY",R5="UP"),AND(J5="SELL",R5="DOWN"),AND(J5="HOLD",R5="FLAT")),"YES","NO")) -> NO | T5: =IF(J5="","",IF(J5="BUY",1,IF(J5="SELL",-1,0))) -> 0 | U5: =IFERROR(IF(OR(J5="",N5="",P5=""),"",IF(T5=0,0,T5*Q5-Settings!$B$4/10000-IF(T5<0,Settings!$B$5/10000,0))),"") -> 0 | W5: =IF($K5="","",$K5*60) -> 1440 | X5: =IF($A5="","",$A5&"|"&$C5&"|"&$D5) -> Netflix|2025|Q3 | Y5: =IFERROR(IF($X5="","",INDEX(LLM_Data_Entry!$H$3:$H$548,MATCH($X5,INDEX(LLM_Data_Entry!$A$3:$A$548&"|"&LLM_Data_Entry!$C$3:$C$548&"|"&LLM_Data_Entry!$D$3:$D$548,0),0))),"") -> HOLD | Z5: =IFERROR(IF($X5="","",INDEX(LLM_Data_Entry!$R$3:$R$548,MATCH($X5,INDEX(LLM_Data_Entry!$A$3:$A$548&"|"&LLM_Data_Entry!$C$3:$C$548&"|"&LLM_Data_Entry!$D$3:$D$548,0),0))),"") -> NO | AB5: release date + stated time in the document (rater worksheet) | AC5: NFLX | AD5: 2025-10-21 | AE5: 124.135 | AF5: 2025-10-22 | AG5: 114.29 | AH5: -0.079308824 | AI5: DOWN | AJ5: NO | AK5: 0 | AL5: =IF($A5="","",IFERROR(INDEX(Company_List!$G$3:$G$207,MATCH($A5,Company_List!$A$3:$A$207,0)),"unassigned")) -> P2 | AM5: Phase 2/Netflix/2025-Q3/NFLX-2025-Q3-press-release-SEC-EX-99-1.htm | AN5: https://www.sec.gov/Archives/edgar/data/1065280/000106528025000404/ex991_q325.htm | AO5: manifest | AP5: =IF($A5="","",IF(COUNTIFS(LLM_Data_Entry!$A$3:$A$548,$A5)>0,"YES","NO")) -> YES | AQ5: =IF($A5="","",IF(COUNTIFS($A$3:$A5,$A5,$C$3:$C5,$C5,$D$3:$D5,$D5)=1,"YES","NO")) -> YES | AR5: =IF($A5="","",IF(AND($C5&"-"&$D5>=Settings!$B$19,$C5&"-"&$D5<=Settings!$B$20),"IN","OUT")) -> IN | AS5: =IF($A5="","",IF($F5="Financial Results","financials",IF($F5="Outlook/Guidance","guidance",IF($F5="Transcript Q&A","qanda",IF($F5="","unrecorded",IF($E5="All","full",IF($E5="","unrecorded",LOWER($E5)&" only"))))))) -> full | AT5: =IF(AND(OR($J5="BUY",$J5="SELL"),ISNUMBER($U5)),$U5,"") | AU5: =IF(AND(OR($J5="BUY",$J5="SELL"),ISNUMBER($AK5)),$AK5,"") | AV5: =IF(ISNUMBER($AT5),ABS(IF(ISNUMBER($I5),$I5,0)-Settings!$B$24),"") | AW5: =IF(ISNUMBER($AV5),$AV5*$AT5,"") | AX5: =IF(ISNUMBER($AU5),ABS(IF(ISNUMBER($I5),$I5,0)-Settings!$B$24),"") | AY5: FROZEN | AZ5: =IF($A5="","",IFERROR(INDEX(Company_List!$H$3:$H$207,MATCH($A5,Company_List!$A$3:$A$207,0)),"unassigned")) -> Communication Services | BC5: =IF($A5="","",IF(COUNTIFS($A$3:$A5,$A5,$C$3:$C5,$C5,$D$3:$D5,$D5,$G$3:$G5,$G5)=1,1,0)) -> 1 | BG5: no | BK5: =IF(OR($H5<>"Human",$S5="",$J5="",$Y5="",$Z5=""),"",IF(EXACT(UPPER($J5),UPPER($Y5)),1,0)) -> 1 | BL5: assumed - no rater record | BM5: 1 | BN5: not publisher-identified | BO5: not publisher-identified | BP5: no | BQ5: yes | BS5: YES
A6: Netflix | B6: =IF(A6="","",_xlfn.XLOOKUP(A6, Company_List!$A:$A, Company_List!$B:$B, "")) -> NFLX | C6: 2025 | D6: Q4 | E6: All | F6: All | G6: Anna | H6: Human | I6: 0.6 | J6: =IF(OR(I6="",Settings!$B$6=""),"",IF(I6>Settings!$B$6,"BUY",IF(I6<-Settings!$B$6,"SELL","HOLD"))) -> BUY | K6: 25 | L6: 46042 | M6: 46042 | N6: 87.26 | O6: 46043 | P6: 82.52 | Q6: =IF(OR(N6="",P6=""),"",ROUND((P6-N6)/N6,4)) -> -0.0543 | R6: =IF(OR(N6="",P6=""),"",IF(Q6>Settings!$B$3/100,"UP",IF(Q6<-Settings!$B$3/100,"DOWN","FLAT"))) -> DOWN | S6: =IF(OR(N6="",P6="",J6=""),"",IF(OR(AND(J6="BUY",R6="UP"),AND(J6="SELL",R6="DOWN"),AND(J6="HOLD",R6="FLAT")),"YES","NO")) -> NO | T6: =IF(J6="","",IF(J6="BUY",1,IF(J6="SELL",-1,0))) -> 1 | U6: =IFERROR(IF(OR(J6="",N6="",P6=""),"",IF(T6=0,0,T6*Q6-Settings!$B$4/10000-IF(T6<0,Settings!$B$5/10000,0))),"") -> -0.0553 | W6: =IF($K6="","",$K6*60) -> 1500 | X6: =IF($A6="","",$A6&"|"&$C6&"|"&$D6) -> Netflix|2025|Q4 | Y6: =IFERROR(IF($X6="","",INDEX(LLM_Data_Entry!$H$3:$H$548,MATCH($X6,INDEX(LLM_Data_Entry!$A$3:$A$548&"|"&LLM_Data_Entry!$C$3:$C$548&"|"&LLM_Data_Entry!$D$3:$D$548,0),0))),"") -> BUY | Z6: =IFERROR(IF($X6="","",INDEX(LLM_Data_Entry!$R$3:$R$548,MATCH($X6,INDEX(LLM_Data_Entry!$A$3:$A$548&"|"&LLM_Data_Entry!$C$3:$C$548&"|"&LLM_Data_Entry!$D$3:$D$548,0),0))),"") -> NO | AB6: release date + stated time in the document (rater worksheet) | AC6: NFLX | AD6: 2026-01-20 | AE6: 87.26 | AF6: 2026-01-21 | AG6: 82.52 | AH6: -0.054320478 | AI6: DOWN | AJ6: NO | AK6: -0.05532 | AL6: =IF($A6="","",IFERROR(INDEX(Company_List!$G$3:$G$207,MATCH($A6,Company_List!$A$3:$A$207,0)),"unassigned")) -> P2 | AM6: Phase 2/Netflix/2025-Q4/NFLX-2025-Q4-press-release-SEC-EX-99-1.htm | AN6: https://www.sec.gov/Archives/edgar/data/1065280/000106528026000033/ex991_q425.htm | AO6: manifest | AP6: =IF($A6="","",IF(COUNTIFS(LLM_Data_Entry!$A$3:$A$548,$A6)>0,"YES","NO")) -> YES | AQ6: =IF($A6="","",IF(COUNTIFS($A$3:$A6,$A6,$C$3:$C6,$C6,$D$3:$D6,$D6)=1,"YES","NO")) -> YES | AR6: =IF($A6="","",IF(AND($C6&"-"&$D6>=Settings!$B$19,$C6&"-"&$D6<=Settings!$B$20),"IN","OUT")) -> IN | AS6: =IF($A6="","",IF($F6="Financial Results","financials",IF($F6="Outlook/Guidance","guidance",IF($F6="Transcript Q&A","qanda",IF($F6="","unrecorded",IF($E6="All","full",IF($E6="","unrecorded",LOWER($E6)&" only"))))))) -> full | AT6: =IF(AND(OR($J6="BUY",$J6="SELL"),ISNUMBER($U6)),$U6,"") -> -0.0553 | AU6: =IF(AND(OR($J6="BUY",$J6="SELL"),ISNUMBER($AK6)),$AK6,"") -> -0.05532 | AV6: =IF(ISNUMBER($AT6),ABS(IF(ISNUMBER($I6),$I6,0)-Settings!$B$24),"") -> 0.6 | AW6: =IF(ISNUMBER($AV6),$AV6*$AT6,"") -> -0.03318 | AX6: =IF(ISNUMBER($AU6),ABS(IF(ISNUMBER($I6),$I6,0)-Settings!$B$24),"") -> 0.6 | AY6: FROZEN | AZ6: =IF($A6="","",IFERROR(INDEX(Company_List!$H$3:$H$207,MATCH($A6,Company_List!$A$3:$A$207,0)),"unassigned")) -> Communication Services | BC6: =IF($A6="","",IF(COUNTIFS($A$3:$A6,$A6,$C$3:$C6,$C6,$D$3:$D6,$D6,$G$3:$G6,$G6)=1,1,0)) -> 1 | BG6: no | BK6: =IF(OR($H6<>"Human",$S6="",$J6="",$Y6="",$Z6=""),"",IF(EXACT(UPPER($J6),UPPER($Y6)),1,0)) -> 1 | BL6: assumed - no rater record | BM6: 1 | BN6: not publisher-identified | BO6: not publisher-identified | BP6: no | BQ6: yes | BS6: YES
A7: Netflix | B7: =IF(A7="","",_xlfn.XLOOKUP(A7, Company_List!$A:$A, Company_List!$B:$B, "")) -> NFLX | C7: 2026 | D7: Q1 | E7: All | F7: All | G7: Meriem | H7: Human | I7: 0.6 | J7: =IF(OR(I7="",Settings!$B$6=""),"",IF(I7>Settings!$B$6,"BUY",IF(I7<-Settings!$B$6,"SELL","HOLD"))) -> BUY | K7: 35 | L7: 46128 | M7: 46128 | N7: 107.79 | O7: 46129 | P7: 96.37 | Q7: =IF(OR(N7="",P7=""),"",ROUND((P7-N7)/N7,4)) -> -0.1059 | R7: =IF(OR(N7="",P7=""),"",IF(Q7>Settings!$B$3/100,"UP",IF(Q7<-Settings!$B$3/100,"DOWN","FLAT"))) -> DOWN | S7: =IF(OR(N7="",P7="",J7=""),"",IF(OR(AND(J7="BUY",R7="UP"),AND(J7="SELL",R7="DOWN"),AND(J7="HOLD",R7="FLAT")),"YES","NO")) -> NO | T7: =IF(J7="","",IF(J7="BUY",1,IF(J7="SELL",-1,0))) -> 1 | U7: =IFERROR(IF(OR(J7="",N7="",P7=""),"",IF(T7=0,0,T7*Q7-Settings!$B$4/10000-IF(T7<0,Settings!$B$5/10000,0))),"") -> -0.1069 | W7: =IF($K7="","",$K7*60) -> 2100 | X7: =IF($A7="","",$A7&"|"&$C7&"|"&$D7) -> Netflix|2026|Q1 | Y7: =IFERROR(IF($X7="","",INDEX(LLM_Data_Entry!$H$3:$H$548,MATCH($X7,INDEX(LLM_Data_Entry!$A$3:$A$548&"|"&LLM_Data_Entry!$C$3:$C$548&"|"&LLM_Data_Entry!$D$3:$D$548,0),0))),"") -> SELL | Z7: =IFERROR(IF($X7="","",INDEX(LLM_Data_Entry!$R$3:$R$548,MATCH($X7,INDEX(LLM_Data_Entry!$A$3:$A$548&"|"&LLM_Data_Entry!$C$3:$C$548&"|"&LLM_Data_Entry!$D$3:$D$548,0),0))),"") -> YES | AB7: price signal — only this window shows an abnormal move | AC7: NFLX | AD7: 2026-04-16 | AE7: 107.79 | AF7: 2026-04-17 | AG7: 96.37 | AH7: -0.10594673 | AI7: DOWN | AJ7: NO | AK7: -0.106947 | AL7: =IF($A7="","",IFERROR(INDEX(Company_List!$G$3:$G$207,MATCH($A7,Company_List!$A$3:$A$207,0)),"unassigned")) -> P2 | AM7: Phase 2/Netflix/Netflix-Inc-_Earnings-Call_2026-04-16T00_00_00_English-1.pdf | AO7: unique filename match | AP7: =IF($A7="","",IF(COUNTIFS(LLM_Data_Entry!$A$3:$A$548,$A7)>0,"YES","NO")) -> YES | AQ7: =IF($A7="","",IF(COUNTIFS($A$3:$A7,$A7,$C$3:$C7,$C7,$D$3:$D7,$D7)=1,"YES","NO")) -> NO | AR7: =IF($A7="","",IF(AND($C7&"-"&$D7>=Settings!$B$19,$C7&"-"&$D7<=Settings!$B$20),"IN","OUT")) -> IN | AS7: =IF($A7="","",IF($F7="Financial Results","financials",IF($F7="Outlook/Guidance","guidance",IF($F7="Transcript Q&A","qanda",IF($F7="","unrecorded",IF($E7="All","full",IF($E7="","unrecorded",LOWER($E7)&" only"))))))) -> full | AT7: =IF(AND(OR($J7="BUY",$J7="SELL"),ISNUMBER($U7)),$U7,"") -> -0.1069 | AU7: =IF(AND(OR($J7="BUY",$J7="SELL"),ISNUMBER($AK7)),$AK7,"") -> -0.106947 | AV7: =IF(ISNUMBER($AT7),ABS(IF(ISNUMBER($I7),$I7,0)-Settings!$B$24),"") -> 0.6 | AW7: =IF(ISNUMBER($AV7),$AV7*$AT7,"") -> -0.06414 | AX7: =IF(ISNUMBER($AU7),ABS(IF(ISNUMBER($I7),$I7,0)-Settings!$B$24),"") -> 0.6 | AY7: FROZEN | AZ7: =IF($A7="","",IFERROR(INDEX(Company_List!$H$3:$H$207,MATCH($A7,Company_List!$A$3:$A$207,0)),"unassigned")) -> Communication Services | BC7: =IF($A7="","",IF(COUNTIFS($A$3:$A7,$A7,$C$3:$C7,$C7,$D$3:$D7,$D7,$G$3:$G7,$G7)=1,1,0)) -> 1 | BG7: no | BK7: =IF(OR($H7<>"Human",$S7="",$J7="",$Y7="",$Z7=""),"",IF(EXACT(UPPER($J7),UPPER($Y7)),1,0)) -> 0 | BL7: assumed - no rater record | BM7: 1 | BN7: S&P Global Market Intelligence (Capital IQ) | BO7: licensed vendor | BP7: no | BQ7: no | BS7: YES
A8: Netflix | B8: =IF(A8="","",_xlfn.XLOOKUP(A8, Company_List!$A:$A, Company_List!$B:$B, "")) -> NFLX | C8: 2025 | D8: Q2 | E8: All | F8: All | G8: Meriem | H8: Human | I8: 0.7 | J8: =IF(OR(I8="",Settings!$B$6=""),"",IF(I8>Settings!$B$6,"BUY",IF(I8<-Settings!$B$6,"SELL","HOLD"))) -> BUY | K8: 55 | L8: 45855 | M8: 45855 | N8: 127.417 | O8: 45856 | P8: 124.2 | Q8: =IF(OR(N8="",P8=""),"",ROUND((P8-N8)/N8,4)) -> -0.0252 | R8: =IF(OR(N8="",P8=""),"",IF(Q8>Settings!$B$3/100,"UP",IF(Q8<-Settings!$B$3/100,"DOWN","FLAT"))) -> DOWN | S8: =IF(OR(N8="",P8="",J8=""),"",IF(OR(AND(J8="BUY",R8="UP"),AND(J8="SELL",R8="DOWN"),AND(J8="HOLD",R8="FLAT")),"YES","NO")) -> NO | T8: =IF(J8="","",IF(J8="BUY",1,IF(J8="SELL",-1,0))) -> 1 | U8: =IFERROR(IF(OR(J8="",N8="",P8=""),"",IF(T8=0,0,T8*Q8-Settings!$B$4/10000-IF(T8<0,Settings!$B$5/10000,0))),"") -> -0.0262 | W8: =IF($K8="","",$K8*60) -> 3300 | X8: =IF($A8="","",$A8&"|"&$C8&"|"&$D8) -> Netflix|2025|Q2 | Y8: =IFERROR(IF($X8="","",INDEX(LLM_Data_Entry!$H$3:$H$548,MATCH($X8,INDEX(LLM_Data_Entry!$A$3:$A$548&"|"&LLM_Data_Entry!$C$3:$C$548&"|"&LLM_Data_Entry!$D$3:$D$548,0),0))),"") -> HOLD | Z8: =IFERROR(IF($X8="","",INDEX(LLM_Data_Entry!$R$3:$R$548,MATCH($X8,INDEX(LLM_Data_Entry!$A$3:$A$548&"|"&LLM_Data_Entry!$C$3:$C$548&"|"&LLM_Data_Entry!$D$3:$D$548,0),0))),"") -> NO | AB8: price signal — only this window shows an abnormal move | AC8: NFLX | AD8: 2025-07-17 | AE8: 127.417 | AF8: 2025-07-18 | AG8: 124.196 | AH8: -0.025279209 | AI8: DOWN | AJ8: NO | AK8: -0.026279 | AL8: =IF($A8="","",IFERROR(INDEX(Company_List!$G$3:$G$207,MATCH($A8,Company_List!$A$3:$A$207,0)),"unassigned")) -> P2 | AM8: Phase 2/Netflix/2025-Q2/NFLX-2025-Q2-press-release-SEC-EX-99-1.htm | AN8: https://www.sec.gov/Archives/edgar/data/1065280/000106528025000322/ex991_q225.htm | AO8: manifest | AP8: =IF($A8="","",IF(COUNTIFS(LLM_Data_Entry!$A$3:$A$548,$A8)>0,"YES","NO")) -> YES | AQ8: =IF($A8="","",IF(COUNTIFS($A$3:$A8,$A8,$C$3:$C8,$C8,$D$3:$D8,$D8)=1,"YES","NO")) -> NO | AR8: =IF($A8="","",IF(AND($C8&"-"&$D8>=Settings!$B$19,$C8&"-"&$D8<=Settings!$B$20),"IN","OUT")) -> IN | AS8: =IF($A8="","",IF($F8="Financial Results","financials",IF($F8="Outlook/Guidance","guidance",IF($F8="Transcript Q&A","qanda",IF($F8="","unrecorded",IF($E8="All","full",IF($E8="","unrecorded",LOWER($E8)&" only"))))))) -> full | AT8: =IF(AND(OR($J8="BUY",$J8="SELL"),ISNUMBER($U8)),$U8,"") -> -0.0262 | AU8: =IF(AND(OR($J8="BUY",$J8="SELL"),ISNUMBER($AK8)),$AK8,"") -> -0.026279 | AV8: =IF(ISNUMBER($AT8),ABS(IF(ISNUMBER($I8),$I8,0)-Settings!$B$24),"") -> 0.7 | AW8: =IF(ISNUMBER($AV8),$AV8*$AT8,"") -> -0.01834 | AX8: =IF(ISNUMBER($AU8),ABS(IF(ISNUMBER($I8),$I8,0)-Settings!$B$24),"") -> 0.7 | AY8: FROZEN | AZ8: =IF($A8="","",IFERROR(INDEX(Company_List!$H$3:$H$207,MATCH($A8,Company_List!$A$3:$A$207,0)),"unassigned")) -> Communication Services | BC8: =IF($A8="","",IF(COUNTIFS($A$3:$A8,$A8,$C$3:$C8,$C8,$D$3:$D8,$D8,$G$3:$G8,$G8)=1,1,0)) -> 1 | BG8: no | BK8: =IF(OR($H8<>"Human",$S8="",$J8="",$Y8="",$Z8=""),"",IF(EXACT(UPPER($J8),UPPER($Y8)),1,0)) -> 0 | BL8: assumed - no rater record | BM8: 1 | BN8: not publisher-identified | BO8: not publisher-identified | BP8: no | BQ8: yes | BS8: YES
A9: Netflix | B9: =IF(A9="","",_xlfn.XLOOKUP(A9, Company_List!$A:$A, Company_List!$B:$B, "")) -> NFLX | C9: 2025 | D9: Q3 | E9: All | F9: All | G9: Meriem | H9: Human | I9: -0.5 | J9: =IF(OR(I9="",Settings!$B$6=""),"",IF(I9>Settings!$B$6,"BUY",IF(I9<-Settings!$B$6,"SELL","HOLD"))) -> SELL | K9: 38 | L9: 45951 | M9: 45951 | N9: 124.135 | O9: 45952 | P9: 114.29 | Q9: =IF(OR(N9="",P9=""),"",ROUND((P9-N9)/N9,4)) -> -0.0793 | R9: =IF(OR(N9="",P9=""),"",IF(Q9>Settings!$B$3/100,"UP",IF(Q9<-Settings!$B$3/100,"DOWN","FLAT"))) -> DOWN | S9: =IF(OR(N9="",P9="",J9=""),"",IF(OR(AND(J9="BUY",R9="UP"),AND(J9="SELL",R9="DOWN"),AND(J9="HOLD",R9="FLAT")),"YES","NO")) -> YES | T9: =IF(J9="","",IF(J9="BUY",1,IF(J9="SELL",-1,0))) -> -1 | U9: =IFERROR(IF(OR(J9="",N9="",P9=""),"",IF(T9=0,0,T9*Q9-Settings!$B$4/10000-IF(T9<0,Settings!$B$5/10000,0))),"") -> 0.0783 | W9: =IF($K9="","",$K9*60) -> 2280 | X9: =IF($A9="","",$A9&"|"&$C9&"|"&$D9) -> Netflix|2025|Q3 | Y9: =IFERROR(IF($X9="","",INDEX(LLM_Data_Entry!$H$3:$H$548,MATCH($X9,INDEX(LLM_Data_Entry!$A$3:$A$548&"|"&LLM_Data_Entry!$C$3:$C$548&"|"&LLM_Data_Entry!$D$3:$D$548,0),0))),"") -> HOLD | Z9: =IFERROR(IF($X9="","",INDEX(LLM_Data_Entry!$R$3:$R$548,MATCH($X9,INDEX(LLM_Data_Entry!$A$3:$A$548&"|"&LLM_Data_Entry!$C$3:$C$548&"|"&LLM_Data_Entry!$D$3:$D$548,0),0))),"") -> NO | AB9: release date + stated time in the document (rater worksheet) | AC9: NFLX | AD9: 2025-10-21 | AE9: 124.135 | AF9: 2025-10-22 | AG9: 114.29 | AH9: -0.079308824 | AI9: DOWN | AJ9: YES | AK9: 0.078309 | AL9: =IF($A9="","",IFERROR(INDEX(Company_List!$G$3:$G$207,MATCH($A9,Company_List!$A$3:$A$207,0)),"unassigned")) -> P2 | AM9: Phase 2/Netflix/2025-Q3/NFLX-2025-Q3-press-release-SEC-EX-99-1.htm | AN9: https://www.sec.gov/Archives/edgar/data/1065280/000106528025000404/ex991_q325.htm | AO9: manifest | AP9: =IF($A9="","",IF(COUNTIFS(LLM_Data_Entry!$A$3:$A$548,$A9)>0,"YES","NO")) -> YES | AQ9: =IF($A9="","",IF(COUNTIFS($A$3:$A9,$A9,$C$3:$C9,$C9,$D$3:$D9,$D9)=1,"YES","NO")) -> NO | AR9: =IF($A9="","",IF(AND($C9&"-"&$D9>=Settings!$B$19,$C9&"-"&$D9<=Settings!$B$20),"IN","OUT")) -> IN | AS9: =IF($A9="","",IF($F9="Financial Results","financials",IF($F9="Outlook/Guidance","guidance",IF($F9="Transcript Q&A","qanda",IF($F9="","unrecorded",IF($E9="All","full",IF($E9="","unrecorded",LOWER($E9)&" only"))))))) -> full | AT9: =IF(AND(OR($J9="BUY",$J9="SELL"),ISNUMBER($U9)),$U9,"") -> 0.0783 | AU9: =IF(AND(OR($J9="BUY",$J9="SELL"),ISNUMBER($AK9)),$AK9,"") -> 0.078309 | AV9: =IF(ISNUMBER($AT9),ABS(IF(ISNUMBER($I9),$I9,0)-Settings!$B$24),"") -> 0.5 | AW9: =IF(ISNUMBER($AV9),$AV9*$AT9,"") -> 0.03915 | AX9: =IF(ISNUMBER($AU9),ABS(IF(ISNUMBER($I9),$I9,0)-Settings!$B$24),"") -> 0.5 | AY9: FROZEN | AZ9: =IF($A9="","",IFERROR(INDEX(Company_List!$H$3:$H$207,MATCH($A9,Company_List!$A$3:$A$207,0)),"unassigned")) -> Communication Services | BC9: =IF($A9="","",IF(COUNTIFS($A$3:$A9,$A9,$C$3:$C9,$C9,$D$3:$D9,$D9,$G$3:$G9,$G9)=1,1,0)) -> 1 | BG9: no | BK9: =IF(OR($H9<>"Human",$S9="",$J9="",$Y9="",$Z9=""),"",IF(EXACT(UPPER($J9),UPPER($Y9)),1,0)) -> 0 | BL9: assumed - no rater record | BM9: 1 | BN9: not publisher-identified | BO9: not publisher-identified | BP9: no | BQ9: yes | BS9: YES
A10: Netflix | B10: =IF(A10="","",_xlfn.XLOOKUP(A10, Company_List!$A:$A, Company_List!$B:$B, "")) -> NFLX | C10: 2025 | D10: Q4 | E10: All | F10: All | G10: Meriem | H10: Human | I10: 0.2 | J10: =IF(OR(I10="",Settings!$B$6=""),"",IF(I10>Settings!$B$6,"BUY",IF(I10<-Settings!$B$6,"SELL","HOLD"))) -> HOLD | K10: 40 | L10: 46042 | M10: 46042 | N10: 87.26 | O10: 46043 | P10: 82.52 | Q10: =IF(OR(N10="",P10=""),"",ROUND((P10-N10)/N10,4)) -> -0.0543 | R10: =IF(OR(N10="",P10=""),"",IF(Q10>Settings!$B$3/100,"UP",IF(Q10<-Settings!$B$3/100,"DOWN","FLAT"))) -> DOWN | S10: =IF(OR(N10="",P10="",J10=""),"",IF(OR(AND(J10="BUY",R10="UP"),AND(J10="SELL",R10="DOWN"),AND(J10="HOLD",R10="FLAT")),"YES","NO")) -> NO | T10: =IF(J10="","",IF(J10="BUY",1,IF(J10="SELL",-1,0))) -> 0 | U10: =IFERROR(IF(OR(J10="",N10="",P10=""),"",IF(T10=0,0,T10*Q10-Settings!$B$4/10000-IF(T10<0,Settings!$B$5/10000,0))),"") -> 0 | W10: =IF($K10="","",$K10*60) -> 2400 | X10: =IF($A10="","",$A10&"|"&$C10&"|"&$D10) -> Netflix|2025|Q4 | Y10: =IFERROR(IF($X10="","",INDEX(LLM_Data_Entry!$H$3:$H$548,MATCH($X10,INDEX(LLM_Data_Entry!$A$3:$A$548&"|"&LLM_Data_Entry!$C$3:$C$548&"|"&LLM_Data_Entry!$D$3:$D$548,0),0))),"") -> BUY | Z10: =IFERROR(IF($X10="","",INDEX(LLM_Data_Entry!$R$3:$R$548,MATCH($X10,INDEX(LLM_Data_Entry!$A$3:$A$548&"|"&LLM_Data_Entry!$C$3:$C$548&"|"&LLM_Data_Entry!$D$3:$D$548,0),0))),"") -> NO | AB10: release date + stated time in the document (rater worksheet) | AC10: NFLX | AD10: 2026-01-20 | AE10: 87.26 | AF10: 2026-01-21 | AG10: 82.52 | AH10: -0.054320478 | AI10: DOWN | AJ10: NO | AK10: 0 | AL10: =IF($A10="","",IFERROR(INDEX(Company_List!$G$3:$G$207,MATCH($A10,Company_List!$A$3:$A$207,0)),"unassigned")) -> P2 | AM10: Phase 2/Netflix/2025-Q4/NFLX-2025-Q4-press-release-SEC-EX-99-1.htm | AN10: https://www.sec.gov/Archives/edgar/data/1065280/000106528026000033/ex991_q425.htm | AO10: manifest | AP10: =IF($A10="","",IF(COUNTIFS(LLM_Data_Entry!$A$3:$A$548,$A10)>0,"YES","NO")) -> YES | AQ10: =IF($A10="","",IF(COUNTIFS($A$3:$A10,$A10,$C$3:$C10,$C10,$D$3:$D10,$D10)=1,"YES","NO")) -> NO | AR10: =IF($A10="","",IF(AND($C10&"-"&$D10>=Settings!$B$19,$C10&"-"&$D10<=Settings!$B$20),"IN","OUT")) -> IN | AS10: =IF($A10="","",IF($F10="Financial Results","financials",IF($F10="Outlook/Guidance","guidance",IF($F10="Transcript Q&A","qanda",IF($F10="","unrecorded",IF($E10="All","full",IF($E10="","unrecorded",LOWER($E10)&" only"))))))) -> full | AT10: =IF(AND(OR($J10="BUY",$J10="SELL"),ISNUMBER($U10)),$U10,"") | AU10: =IF(AND(OR($J10="BUY",$J10="SELL"),ISNUMBER($AK10)),$AK10,"") | AV10: =IF(ISNUMBER($AT10),ABS(IF(ISNUMBER($I10),$I10,0)-Settings!$B$24),"") | AW10: =IF(ISNUMBER($AV10),$AV10*$AT10,"") | AX10: =IF(ISNUMBER($AU10),ABS(IF(ISNUMBER($I10),$I10,0)-Settings!$B$24),"") | AY10: FROZEN | AZ10: =IF($A10="","",IFERROR(INDEX(Company_List!$H$3:$H$207,MATCH($A10,Company_List!$A$3:$A$207,0)),"unassigned")) -> Communication Services | BC10: =IF($A10="","",IF(COUNTIFS($A$3:$A10,$A10,$C$3:$C10,$C10,$D$3:$D10,$D10,$G$3:$G10,$G10)=1,1,0)) -> 1 | BG10: no | BK10: =IF(OR($H10<>"Human",$S10="",$J10="",$Y10="",$Z10=""),"",IF(EXACT(UPPER($J10),UPPER($Y10)),1,0)) -> 0 | BL10: assumed - no rater record | BM10: 1 | BN10: not publisher-identified | BO10: not publisher-identified | BP10: no | BQ10: yes | BS10: YES
A11: Netflix | B11: =IF(A11="","",_xlfn.XLOOKUP(A11, Company_List!$A:$A, Company_List!$B:$B, "")) -> NFLX | C11: 2025 | D11: Q1 | E11: All | F11: All | G11: Dragos | H11: Human | I11: 0.65 | J11: =IF(OR(I11="",Settings!$B$6=""),"",IF(I11>Settings!$B$6,"BUY",IF(I11<-Settings!$B$6,"SELL","HOLD"))) -> BUY | K11: 42 | L11: 45764 | M11: 45764 | N11: 97.303 | O11: 45765 | P11: 98.44 | Q11: =IF(OR(N11="",P11=""),"",ROUND((P11-N11)/N11,4)) -> 0.0117 | R11: =IF(OR(N11="",P11=""),"",IF(Q11>Settings!$B$3/100,"UP",IF(Q11<-Settings!$B$3/100,"DOWN","FLAT"))) -> FLAT | S11: =IF(OR(N11="",P11="",J11=""),"",IF(OR(AND(J11="BUY",R11="UP"),AND(J11="SELL",R11="DOWN"),AND(J11="HOLD",R11="FLAT")),"YES","NO")) -> NO | T11: =IF(J11="","",IF(J11="BUY",1,IF(J11="SELL",-1,0))) -> 1 | U11: =IFERROR(IF(OR(J11="",N11="",P11=""),"",IF(T11=0,0,T11*Q11-Settings!$B$4/10000-IF(T11<0,Settings!$B$5/10000,0))),"") -> 0.0107 | V11: CORRECTION: replaces my existing row currently mislabeled '2025 Q4' (it holds this Q1 data). Clean beat, margin expansion, guide tracking above midpoint; valuation full. Sealed 29 Jun, ±1% band (correct under my sealed band). | W11: =IF($K11="","",$K11*60) -> 2520 | X11: =IF($A11="","",$A11&"|"&$C11&"|"&$D11) -> Netflix|2025|Q1 | Y11: =IFERROR(IF($X11="","",INDEX(LLM_Data_Entry!$H$3:$H$548,MATCH($X11,INDEX(LLM_Data_Entry!$A$3:$A$548&"|"&LLM_Data_Entry!$C$3:$C$548&"|"&LLM_Data_Entry!$D$3:$D$548,0),0))),"") -> SELL | Z11: =IFERROR(IF($X11="","",INDEX(LLM_Data_Entry!$R$3:$R$548,MATCH($X11,INDEX(LLM_Data_Entry!$A$3:$A$548&"|"&LLM_Data_Entry!$C$3:$C$548&"|"&LLM_Data_Entry!$D$3:$D$548,0),0))),"") -> NO | AB11: release date + stated time in the document (rater worksheet) | AC11: NFLX | AD11: 2025-04-17 | AE11: 97.303 | AF11: 2025-04-21 | AG11: 98.44 | AH11: 0.011685159 | AI11: FLAT | AJ11: NO | AK11: 0.010685 | AL11: =IF($A11="","",IFERROR(INDEX(Company_List!$G$3:$G$207,MATCH($A11,Company_List!$A$3:$A$207,0)),"unassigned")) -> P2 | AM11: Phase 2/Netflix/2025-Q1/NFLX-2025-Q1-press-release-SEC-EX-99-1.htm | AN11: https://www.sec.gov/Archives/edgar/data/1065280/000106528025000175/ex991_q125.htm | AO11: manifest | AP11: =IF($A11="","",IF(COUNTIFS(LLM_Data_Entry!$A$3:$A$548,$A11)>0,"YES","NO")) -> YES | AQ11: =IF($A11="","",IF(COUNTIFS($A$3:$A11,$A11,$C$3:$C11,$C11,$D$3:$D11,$D11)=1,"YES","NO")) -> YES | AR11: =IF($A11="","",IF(AND($C11&"-"&$D11>=Settings!$B$19,$C11&"-"&$D11<=Settings!$B$20),"IN","OUT")) -> IN | AS11: =IF($A11="","",IF($F11="Financial Results","financials",IF($F11="Outlook/Guidance","guidance",IF($F11="Transcript Q&A","qanda",IF($F11="","unrecorded",IF($E11="All","full",IF($E11="","unrecorded",LOWER($E11)&" only"))))))) -> full | AT11: =IF(AND(OR($J11="BUY",$J11="SELL"),ISNUMBER($U11)),$U11,"") -> 0.0107 | AU11: =IF(AND(OR($J11="BUY",$J11="SELL"),ISNUMBER($AK11)),$AK11,"") -> 0.010685 | AV11: =IF(ISNUMBER($AT11),ABS(IF(ISNUMBER($I11),$I11,0)-Settings!$B$24),"") -> 0.65 | AW11: =IF(ISNUMBER($AV11),$AV11*$AT11,"") -> 0.006955 | AX11: =IF(ISNUMBER($AU11),ABS(IF(ISNUMBER($I11),$I11,0)-Settings!$B$24),"") -> 0.65 | AY11: FROZEN | AZ11: =IF($A11="","",IFERROR(INDEX(Company_List!$H$3:$H$207,MATCH($A11,Company_List!$A$3:$A$207,0)),"unassigned")) -> Communication Services | BC11: =IF($A11="","",IF(COUNTIFS($A$3:$A11,$A11,$C$3:$C11,$C11,$D$3:$D11,$D11,$G$3:$G11,$G11)=1,1,0)) -> 1 | BG11: no | BK11: =IF(OR($H11<>"Human",$S11="",$J11="",$Y11="",$Z11=""),"",IF(EXACT(UPPER($J11),UPPER($Y11)),1,0)) -> 0 | BL11: assumed - no rater record | BM11: 1 | BN11: not publisher-identified | BO11: not publisher-identified | BP11: no | BQ11: yes | BS11: YES
A12: Netflix | B12: =IF(A12="","",_xlfn.XLOOKUP(A12, Company_List!$A:$A, Company_List!$B:$B, "")) -> NFLX | C12: 2025 | D12: Q2 | E12: All | F12: All | G12: Dragos | H12: Human | I12: 0.55 | J12: =IF(OR(I12="",Settings!$B$6=""),"",IF(I12>Settings!$B$6,"BUY",IF(I12<-Settings!$B$6,"SELL","HOLD"))) -> BUY | K12: 38 | L12: 45855 | M12: 45855 | N12: 127.417 | O12: 45856 | P12: 124.2 | Q12: =IF(OR(N12="",P12=""),"",ROUND((P12-N12)/N12,4)) -> -0.0252 | R12: =IF(OR(N12="",P12=""),"",IF(Q12>Settings!$B$3/100,"UP",IF(Q12<-Settings!$B$3/100,"DOWN","FLAT"))) -> DOWN | S12: =IF(OR(N12="",P12="",J12=""),"",IF(OR(AND(J12="BUY",R12="UP"),AND(J12="SELL",R12="DOWN"),AND(J12="HOLD",R12="FLAT")),"YES","NO")) -> NO | T12: =IF(J12="","",IF(J12="BUY",1,IF(J12="SELL",-1,0))) -> 1 | U12: =IFERROR(IF(OR(J12="",N12="",P12=""),"",IF(T12=0,0,T12*Q12-Settings!$B$4/10000-IF(T12<0,Settings!$B$5/10000,0))),"") -> -0.0262 | V12: Beat-and-raise but raise mostly FX; H2 margin step-down guided; stock priced for perfection. NOTE: my sealed next-day open is 124.20 (-2.53%); sheet's existing Q2 rows show 129.92 - flag to Anna/Ben. | W12: =IF($K12="","",$K12*60) -> 2280 | X12: =IF($A12="","",$A12&"|"&$C12&"|"&$D12) -> Netflix|2025|Q2 | Y12: =IFERROR(IF($X12="","",INDEX(LLM_Data_Entry!$H$3:$H$548,MATCH($X12,INDEX(LLM_Data_Entry!$A$3:$A$548&"|"&LLM_Data_Entry!$C$3:$C$548&"|"&LLM_Data_Entry!$D$3:$D$548,0),0))),"") -> HOLD | Z12: =IFERROR(IF($X12="","",INDEX(LLM_Data_Entry!$R$3:$R$548,MATCH($X12,INDEX(LLM_Data_Entry!$A$3:$A$548&"|"&LLM_Data_Entry!$C$3:$C$548&"|"&LLM_Data_Entry!$D$3:$D$548,0),0))),"") -> NO | AB12: price signal — only this window shows an abnormal move | AC12: NFLX | AD12: 2025-07-17 | AE12: 127.417 | AF12: 2025-07-18 | AG12: 124.196 | AH12: -0.025279209 | AI12: DOWN | AJ12: NO | AK12: -0.026279 | AL12: =IF($A12="","",IFERROR(INDEX(Company_List!$G$3:$G$207,MATCH($A12,Company_List!$A$3:$A$207,0)),"unassigned")) -> P2 | AM12: Phase 2/Netflix/2025-Q2/NFLX-2025-Q2-press-release-SEC-EX-99-1.htm | AN12: https://www.sec.gov/Archives/edgar/data/1065280/000106528025000322/ex991_q225.htm | AO12: manifest | AP12: =IF($A12="","",IF(COUNTIFS(LLM_Data_Entry!$A$3:$A$548,$A12)>0,"YES","NO")) -> YES | AQ12: =IF($A12="","",IF(COUNTIFS($A$3:$A12,$A12,$C$3:$C12,$C12,$D$3:$D12,$D12)=1,"YES","NO")) -> NO | AR12: =IF($A12="","",IF(AND($C12&"-"&$D12>=Settings!$B$19,$C12&"-"&$D12<=Settings!$B$20),"IN","OUT")) -> IN | AS12: =IF($A12="","",IF($F12="Financial Results","financials",IF($F12="Outlook/Guidance","guidance",IF($F12="Transcript Q&A","qanda",IF($F12="","unrecorded",IF($E12="All","full",IF($E12="","unrecorded",LOWER($E12)&" only"))))))) -> full | AT12: =IF(AND(OR($J12="BUY",$J12="SELL"),ISNUMBER($U12)),$U12,"") -> -0.0262 | AU12: =IF(AND(OR($J12="BUY",$J12="SELL"),ISNUMBER($AK12)),$AK12,"") -> -0.026279 | AV12: =IF(ISNUMBER($AT12),ABS(IF(ISNUMBER($I12),$I12,0)-Settings!$B$24),"") -> 0.55 | AW12: =IF(ISNUMBER($AV12),$AV12*$AT12,"") -> -0.01441 | AX12: =IF(ISNUMBER($AU12),ABS(IF(ISNUMBER($I12),$I12,0)-Settings!$B$24),"") -> 0.55 | AY12: FROZEN | AZ12: =IF($A12="","",IFERROR(INDEX(Company_List!$H$3:$H$207,MATCH($A12,Company_List!$A$3:$A$207,0)),"unassigned")) -> Communication Services | BC12: =IF($A12="","",IF(COUNTIFS($A$3:$A12,$A12,$C$3:$C12,$C12,$D$3:$D12,$D12,$G$3:$G12,$G12)=1,1,0)) -> 1 | BG12: no | BK12: =IF(OR($H12<>"Human",$S12="",$J12="",$Y12="",$Z12=""),"",IF(EXACT(UPPER($J12),UPPER($Y12)),1,0)) -> 0 | BL12: attested - the note states the score was sealed | BM12: 1 | BN12: not publisher-identified | BO12: not publisher-identified | BP12: no | BQ12: yes | BS12: YES
A13: Netflix | B13: =IF(A13="","",_xlfn.XLOOKUP(A13, Company_List!$A:$A, Company_List!$B:$B, "")) -> NFLX | C13: 2025 | D13: Q3 | E13: All | F13: All | G13: Dragos | H13: Human | I13: 0.45 | J13: =IF(OR(I13="",Settings!$B$6=""),"",IF(I13>Settings!$B$6,"BUY",IF(I13<-Settings!$B$6,"SELL","HOLD"))) -> BUY | K13: 55 | L13: 45951 | M13: 45951 | N13: 124.135 | O13: 45952 | P13: 114.29 | Q13: =IF(OR(N13="",P13=""),"",ROUND((P13-N13)/N13,4)) -> -0.0793 | R13: =IF(OR(N13="",P13=""),"",IF(Q13>Settings!$B$3/100,"UP",IF(Q13<-Settings!$B$3/100,"DOWN","FLAT"))) -> DOWN | S13: =IF(OR(N13="",P13="",J13=""),"",IF(OR(AND(J13="BUY",R13="UP"),AND(J13="SELL",R13="DOWN"),AND(J13="HOLD",R13="FLAT")),"YES","NO")) -> NO | T13: =IF(J13="","",IF(J13="BUY",1,IF(J13="SELL",-1,0))) -> 1 | U13: =IFERROR(IF(OR(J13="",N13="",P13=""),"",IF(T13=0,0,T13*Q13-Settings!$B$4/10000-IF(T13<0,Settings!$B$5/10000,0))),"") -> -0.0803 | V13: Headline EPS miss (Brazil CIDE tax charge), guidance vacuum until January, rich valuation - sold first, reasoned later. | W13: =IF($K13="","",$K13*60) -> 3300 | X13: =IF($A13="","",$A13&"|"&$C13&"|"&$D13) -> Netflix|2025|Q3 | Y13: =IFERROR(IF($X13="","",INDEX(LLM_Data_Entry!$H$3:$H$548,MATCH($X13,INDEX(LLM_Data_Entry!$A$3:$A$548&"|"&LLM_Data_Entry!$C$3:$C$548&"|"&LLM_Data_Entry!$D$3:$D$548,0),0))),"") -> HOLD | Z13: =IFERROR(IF($X13="","",INDEX(LLM_Data_Entry!$R$3:$R$548,MATCH($X13,INDEX(LLM_Data_Entry!$A$3:$A$548&"|"&LLM_Data_Entry!$C$3:$C$548&"|"&LLM_Data_Entry!$D$3:$D$548,0),0))),"") -> NO | AB13: release date + stated time in the document (rater worksheet) | AC13: NFLX | AD13: 2025-10-21 | AE13: 124.135 | AF13: 2025-10-22 | AG13: 114.29 | AH13: -0.079308824 | AI13: DOWN | AJ13: NO | AK13: -0.080309 | AL13: =IF($A13="","",IFERROR(INDEX(Company_List!$G$3:$G$207,MATCH($A13,Company_List!$A$3:$A$207,0)),"unassigned")) -> P2 | AM13: Phase 2/Netflix/2025-Q3/NFLX-2025-Q3-press-release-SEC-EX-99-1.htm | AN13: https://www.sec.gov/Archives/edgar/data/1065280/000106528025000404/ex991_q325.htm | AO13: manifest | AP13: =IF($A13="","",IF(COUNTIFS(LLM_Data_Entry!$A$3:$A$548,$A13)>0,"YES","NO")) -> YES | AQ13: =IF($A13="","",IF(COUNTIFS($A$3:$A13,$A13,$C$3:$C13,$C13,$D$3:$D13,$D13)=1,"YES","NO")) -> NO | AR13: =IF($A13="","",IF(AND($C13&"-"&$D13>=Settings!$B$19,$C13&"-"&$D13<=Settings!$B$20),"IN","OUT")) -> IN | AS13: =IF($A13="","",IF($F13="Financial Results","financials",IF($F13="Outlook/Guidance","guidance",IF($F13="Transcript Q&A","qanda",IF($F13="","unrecorded",IF($E13="All","full",IF($E13="","unrecorded",LOWER($E13)&" only"))))))) -> full | AT13: =IF(AND(OR($J13="BUY",$J13="SELL"),ISNUMBER($U13)),$U13,"") -> -0.0803 | AU13: =IF(AND(OR($J13="BUY",$J13="SELL"),ISNUMBER($AK13)),$AK13,"") -> -0.080309 | AV13: =IF(ISNUMBER($AT13),ABS(IF(ISNUMBER($I13),$I13,0)-Settings!$B$24),"") -> 0.45 | AW13: =IF(ISNUMBER($AV13),$AV13*$AT13,"") -> -0.036135 | AX13: =IF(ISNUMBER($AU13),ABS(IF(ISNUMBER($I13),$I13,0)-Settings!$B$24),"") -> 0.45 | AY13: FROZEN | AZ13: =IF($A13="","",IFERROR(INDEX(Company_List!$H$3:$H$207,MATCH($A13,Company_List!$A$3:$A$207,0)),"unassigned")) -> Communication Services | BC13: =IF($A13="","",IF(COUNTIFS($A$3:$A13,$A13,$C$3:$C13,$C13,$D$3:$D13,$D13,$G$3:$G13,$G13)=1,1,0)) -> 1 | BG13: no | BK13: =IF(OR($H13<>"Human",$S13="",$J13="",$Y13="",$Z13=""),"",IF(EXACT(UPPER($J13),UPPER($Y13)),1,0)) -> 0 | BL13: assumed - no rater record | BM13: 1 | BN13: not publisher-identified | BO13: not publisher-identified | BP13: no | BQ13: yes | BS13: YES
A14: Netflix | B14: =IF(A14="","",_xlfn.XLOOKUP(A14, Company_List!$A:$A, Company_List!$B:$B, "")) -> NFLX | C14: 2025 | D14: Q4 | E14: All | F14: All | G14: Dragos | H14: Human | I14: 0.6 | J14: =IF(OR(I14="",Settings!$B$6=""),"",IF(I14>Settings!$B$6,"BUY",IF(I14<-Settings!$B$6,"SELL","HOLD"))) -> BUY | K14: 45 | L14: 46042 | M14: 46042 | N14: 87.26 | O14: 46043 | P14: 82.52 | Q14: =IF(OR(N14="",P14=""),"",ROUND((P14-N14)/N14,4)) -> -0.0543 | R14: =IF(OR(N14="",P14=""),"",IF(Q14>Settings!$B$3/100,"UP",IF(Q14<-Settings!$B$3/100,"DOWN","FLAT"))) -> DOWN | S14: =IF(OR(N14="",P14="",J14=""),"",IF(OR(AND(J14="BUY",R14="UP"),AND(J14="SELL",R14="DOWN"),AND(J14="HOLD",R14="FLAT")),"YES","NO")) -> NO | T14: =IF(J14="","",IF(J14="BUY",1,IF(J14="SELL",-1,0))) -> 1 | U14: =IFERROR(IF(OR(J14="",N14="",P14=""),"",IF(T14=0,0,T14*Q14-Settings!$B$4/10000-IF(T14<0,Settings!$B$5/10000,0))),"") -> -0.0553 | V14: Clean beat + $51B 2026 guide, but growth decelerating 16%->14% and WBD deal overhang; I under-weighted the forward risk. | W14: =IF($K14="","",$K14*60) -> 2700 | X14: =IF($A14="","",$A14&"|"&$C14&"|"&$D14) -> Netflix|2025|Q4 | Y14: =IFERROR(IF($X14="","",INDEX(LLM_Data_Entry!$H$3:$H$548,MATCH($X14,INDEX(LLM_Data_Entry!$A$3:$A$548&"|"&LLM_Data_Entry!$C$3:$C$548&"|"&LLM_Data_Entry!$D$3:$D$548,0),0))),"") -> BUY | Z14: =IFERROR(IF($X14="","",INDEX(LLM_Data_Entry!$R$3:$R$548,MATCH($X14,INDEX(LLM_Data_Entry!$A$3:$A$548&"|"&LLM_Data_Entry!$C$3:$C$548&"|"&LLM_Data_Entry!$D$3:$D$548,0),0))),"") -> NO | AB14: release date + stated time in the document (rater worksheet) | AC14: NFLX | AD14: 2026-01-20 | AE14: 87.26 | AF14: 2026-01-21 | AG14: 82.52 | AH14: -0.054320478 | AI14: DOWN | AJ14: NO | AK14: -0.05532 | AL14: =IF($A14="","",IFERROR(INDEX(Company_List!$G$3:$G$207,MATCH($A14,Company_List!$A$3:$A$207,0)),"unassigned")) -> P2 | AM14: Phase 2/Netflix/2025-Q4/NFLX-2025-Q4-press-release-SEC-EX-99-1.htm | AN14: https://www.sec.gov/Archives/edgar/data/1065280/000106528026000033/ex991_q425.htm | AO14: manifest | AP14: =IF($A14="","",IF(COUNTIFS(LLM_Data_Entry!$A$3:$A$548,$A14)>0,"YES","NO")) -> YES | AQ14: =IF($A14="","",IF(COUNTIFS($A$3:$A14,$A14,$C$3:$C14,$C14,$D$3:$D14,$D14)=1,"YES","NO")) -> NO | AR14: =IF($A14="","",IF(AND($C14&"-"&$D14>=Settings!$B$19,$C14&"-"&$D14<=Settings!$B$20),"IN","OUT")) -> IN | AS14: =IF($A14="","",IF($F14="Financial Results","financials",IF($F14="Outlook/Guidance","guidance",IF($F14="Transcript Q&A","qanda",IF($F14="","unrecorded",IF($E14="All","full",IF($E14="","unrecorded",LOWER($E14)&" only"))))))) -> full | AT14: =IF(AND(OR($J14="BUY",$J14="SELL"),ISNUMBER($U14)),$U14,"") -> -0.0553 | AU14: =IF(AND(OR($J14="BUY",$J14="SELL"),ISNUMBER($AK14)),$AK14,"") -> -0.05532 | AV14: =IF(ISNUMBER($AT14),ABS(IF(ISNUMBER($I14),$I14,0)-Settings!$B$24),"") -> 0.6 | AW14: =IF(ISNUMBER($AV14),$AV14*$AT14,"") -> -0.03318 | AX14: =IF(ISNUMBER($AU14),ABS(IF(ISNUMBER($I14),$I14,0)-Settings!$B$24),"") -> 0.6 | AY14: FROZEN | AZ14: =IF($A14="","",IFERROR(INDEX(Company_List!$H$3:$H$207,MATCH($A14,Company_List!$A$3:$A$207,0)),"unassigned")) -> Communication Services | BC14: =IF($A14="","",IF(COUNTIFS($A$3:$A14,$A14,$C$3:$C14,$C14,$D$3:$D14,$D14,$G$3:$G14,$G14)=1,1,0)) -> 1 | BG14: no | BK14: =IF(OR($H14<>"Human",$S14="",$J14="",$Y14="",$Z14=""),"",IF(EXACT(UPPER($J14),UPPER($Y14)),1,0)) -> 1 | BL14: assumed - no rater record | BM14: 1 | BN14: not publisher-identified | BO14: not publisher-identified | BP14: no | BQ14: yes | BS14: YES
A15: Nvidia | B15: =IF(A15="","",_xlfn.XLOOKUP(A15, Company_List!$A:$A, Company_List!$B:$B, "")) -> NVDA | C15: 2025 | D15: Q1 | E15: All | F15: All | G15: Dragos | H15: Human | I15: 0.55 | J15: =IF(OR(I15="",Settings!$B$6=""),"",IF(I15>Settings!$B$6,"BUY",IF(I15<-Settings!$B$6,"SELL","HOLD"))) -> BUY | K15: 50 | L15: 45714 | M15: 45714 | N15: 131.28 | O15: 45715 | P15: 135 | Q15: =IF(OR(N15="",P15=""),"",ROUND((P15-N15)/N15,4)) -> 0.0283 | R15: =IF(OR(N15="",P15=""),"",IF(Q15>Settings!$B$3/100,"UP",IF(Q15<-Settings!$B$3/100,"DOWN","FLAT"))) -> UP | S15: =IF(OR(N15="",P15="",J15=""),"",IF(OR(AND(J15="BUY",R15="UP"),AND(J15="SELL",R15="DOWN"),AND(J15="HOLD",R15="FLAT")),"YES","NO")) -> YES | T15: =IF(J15="","",IF(J15="BUY",1,IF(J15="SELL",-1,0))) -> 1 | U15: =IFERROR(IF(OR(J15="",N15="",P15=""),"",IF(T15=0,0,T15*Q15-Settings!$B$4/10000-IF(T15<0,Settings!$B$5/10000,0))),"") -> 0.0273 | V15: NVIDIA fiscal Q4 FY25, released 26 Feb 2025 (calendar label by release date). Beat on every line but margin-trough guide (71%), growth 262%->65%, tariffs unknown. Opened +2.8% then closed -8.5% - overnight window called it BUY. | W15: =IF($K15="","",$K15*60) -> 3000 | X15: =IF($A15="","",$A15&"|"&$C15&"|"&$D15) -> Nvidia|2025|Q1 | Y15: =IFERROR(IF($X15="","",INDEX(LLM_Data_Entry!$H$3:$H$548,MATCH($X15,INDEX(LLM_Data_Entry!$A$3:$A$548&"|"&LLM_Data_Entry!$C$3:$C$548&"|"&LLM_Data_Entry!$D$3:$D$548,0),0))),"") -> SELL | Z15: =IFERROR(IF($X15="","",INDEX(LLM_Data_Entry!$R$3:$R$548,MATCH($X15,INDEX(LLM_Data_Entry!$A$3:$A$548&"|"&LLM_Data_Entry!$C$3:$C$548&"|"&LLM_Data_Entry!$D$3:$D$548,0),0))),"") -> NO | AB15: release date + stated time in the document (rater worksheet) | AC15: NVDA | AD15: 2025-02-26 | AE15: 131.0842 | AF15: 2025-02-27 | AG15: 134.7987 | AH15: 0.028336475 | AI15: UP | AJ15: YES | AK15: 0.027336 | AL15: =IF($A15="","",IFERROR(INDEX(Company_List!$G$3:$G$207,MATCH($A15,Company_List!$A$3:$A$207,0)),"unassigned")) -> P2 | AM15: Phase 2/Nvidia/Q2 2025/NVDA-Q1FY26-press-release-SEC-EX99-1.htm; Phase 2/Nvidia/Q2 2025/NVDA-Q1FY26-earnings-call-transcript-AlphaStreet.html; Phase 2/Nvidia/Q2 2025/NVDA-Q1FY26-CFO-commentary-SEC-EX99-2.htm; Phase 2/Nvidia/Q1 2025/NVDA-Q4FY25-press-release-SEC-EX99-1.htm; Phase 2/Nvidia/Q1 2025/NVDA-Q4FY25-earnings-call-transcript-MotleyFool.html; Phase 2/Nvidia/Q1 2025/NVDA-Q4FY25-CFO-commentary-SEC-EX99-2.htm | AO15: whole bundle (Document = All) | AP15: =IF($A15="","",IF(COUNTIFS(LLM_Data_Entry!$A$3:$A$548,$A15)>0,"YES","NO")) -> YES | AQ15: =IF($A15="","",IF(COUNTIFS($A$3:$A15,$A15,$C$3:$C15,$C15,$D$3:$D15,$D15)=1,"YES","NO")) -> YES | AR15: =IF($A15="","",IF(AND($C15&"-"&$D15>=Settings!$B$19,$C15&"-"&$D15<=Settings!$B$20),"IN","OUT")) -> IN | AS15: =IF($A15="","",IF($F15="Financial Results","financials",IF($F15="Outlook/Guidance","guidance",IF($F15="Transcript Q&A","qanda",IF($F15="","unrecorded",IF($E15="All","full",IF($E15="","unrecorded",LOWER($E15)&" only"))))))) -> full | AT15: =IF(AND(OR($J15="BUY",$J15="SELL"),ISNUMBER($U15)),$U15,"") -> 0.0273 | AU15: =IF(AND(OR($J15="BUY",$J15="SELL"),ISNUMBER($AK15)),$AK15,"") -> 0.027336 | AV15: =IF(ISNUMBER($AT15),ABS(IF(ISNUMBER($I15),$I15,0)-Settings!$B$24),"") -> 0.55 | AW15: =IF(ISNUMBER($AV15),$AV15*$AT15,"") -> 0.015015 | AX15: =IF(ISNUMBER($AU15),ABS(IF(ISNUMBER($I15),$I15,0)-Settings!$B$24),"") -> 0.55 | AY15: FROZEN | AZ15: =IF($A15="","",IFERROR(INDEX(Company_List!$H$3:$H$207,MATCH($A15,Company_List!$A$3:$A$207,0)),"unassigned")) -> Information Technology | BC15: =IF($A15="","",IF(COUNTIFS($A$3:$A15,$A15,$C$3:$C15,$C15,$D$3:$D15,$D15,$G$3:$G15,$G15)=1,1,0)) -> 1 | BG15: no | BK15: =IF(OR($H15<>"Human",$S15="",$J15="",$Y15="",$Z15=""),"",IF(EXACT(UPPER($J15),UPPER($Y15)),1,0)) -> 0 | BL15: assumed - blind unless stated otherwise; the note names the realised move (query E-a, settled 10 Aug 2026) | BM15: 6 | BN15: The Motley Fool | BO15: free to read, copyright asserted | BP15: no | BQ15: yes | BS15: YES
A16: Nvidia | B16: =IF(A16="","",_xlfn.XLOOKUP(A16, Company_List!$A:$A, Company_List!$B:$B, "")) -> NVDA | C16: 2025 | D16: Q2 | E16: All | F16: All | G16: Dragos | H16: Human | I16: 0.35 | J16: =IF(OR(I16="",Settings!$B$6=""),"",IF(I16>Settings!$B$6,"BUY",IF(I16<-Settings!$B$6,"SELL","HOLD"))) -> BUY | K16: 48 | L16: 45805 | M16: 45805 | N16: 134.81 | O16: 45806 | P16: 142.25 | Q16: =IF(OR(N16="",P16=""),"",ROUND((P16-N16)/N16,4)) -> 0.0552 | R16: =IF(OR(N16="",P16=""),"",IF(Q16>Settings!$B$3/100,"UP",IF(Q16<-Settings!$B$3/100,"DOWN","FLAT"))) -> UP | S16: =IF(OR(N16="",P16="",J16=""),"",IF(OR(AND(J16="BUY",R16="UP"),AND(J16="SELL",R16="DOWN"),AND(J16="HOLD",R16="FLAT")),"YES","NO")) -> YES | T16: =IF(J16="","",IF(J16="BUY",1,IF(J16="SELL",-1,0))) -> 1 | U16: =IFERROR(IF(OR(J16="",N16="",P16=""),"",IF(T16=0,0,T16*Q16-Settings!$B$4/10000-IF(T16<0,Settings!$B$5/10000,0))),"") -> 0.0542 | V16: NVIDIA fiscal Q1 FY26, released 28 May 2025. Ugly headline (China/H20 charge) but underlying demand intact; market looked through it. | W16: =IF($K16="","",$K16*60) -> 2880 | X16: =IF($A16="","",$A16&"|"&$C16&"|"&$D16) -> Nvidia|2025|Q2 | Y16: =IFERROR(IF($X16="","",INDEX(LLM_Data_Entry!$H$3:$H$548,MATCH($X16,INDEX(LLM_Data_Entry!$A$3:$A$548&"|"&LLM_Data_Entry!$C$3:$C$548&"|"&LLM_Data_Entry!$D$3:$D$548,0),0))),"") -> HOLD | Z16: =IFERROR(IF($X16="","",INDEX(LLM_Data_Entry!$R$3:$R$548,MATCH($X16,INDEX(LLM_Data_Entry!$A$3:$A$548&"|"&LLM_Data_Entry!$C$3:$C$548&"|"&LLM_Data_Entry!$D$3:$D$548,0),0))),"") -> NO | AB16: release date + stated time in the document (rater worksheet) | AC16: NVDA | AD16: 2025-05-28 | AE16: 134.6213 | AF16: 2025-05-29 | AG16: 142.0509 | AH16: 0.055188774 | AI16: UP | AJ16: YES | AK16: 0.054189 | AL16: =IF($A16="","",IFERROR(INDEX(Company_List!$G$3:$G$207,MATCH($A16,Company_List!$A$3:$A$207,0)),"unassigned")) -> P2 | AM16: Phase 2/Nvidia/Q3 2025/NVDA-Q2FY26-press-release-SEC-EX99-1.htm; Phase 2/Nvidia/Q3 2025/NVDA-Q2FY26-earnings-call-transcript-AlphaStreet.html; Phase 2/Nvidia/Q3 2025/NVDA-Q2FY26-CFO-commentary-SEC-EX99-2.htm; Phase 2/Nvidia/Q2 2025/NVDA-Q1FY26-press-release-SEC-EX99-1.htm; Phase 2/Nvidia/Q2 2025/NVDA-Q1FY26-earnings-call-transcript-AlphaStreet.html; Phase 2/Nvidia/Q2 2025/NVDA-Q1FY26-CFO-commentary-SEC-EX99-2.htm | AO16: whole bundle (Document = All) | AP16: =IF($A16="","",IF(COUNTIFS(LLM_Data_Entry!$A$3:$A$548,$A16)>0,"YES","NO")) -> YES | AQ16: =IF($A16="","",IF(COUNTIFS($A$3:$A16,$A16,$C$3:$C16,$C16,$D$3:$D16,$D16)=1,"YES","NO")) -> YES | AR16: =IF($A16="","",IF(AND($C16&"-"&$D16>=Settings!$B$19,$C16&"-"&$D16<=Settings!$B$20),"IN","OUT")) -> IN | AS16: =IF($A16="","",IF($F16="Financial Results","financials",IF($F16="Outlook/Guidance","guidance",IF($F16="Transcript Q&A","qanda",IF($F16="","unrecorded",IF($E16="All","full",IF($E16="","unrecorded",LOWER($E16)&" only"))))))) -> full | AT16: =IF(AND(OR($J16="BUY",$J16="SELL"),ISNUMBER($U16)),$U16,"") -> 0.0542 | AU16: =IF(AND(OR($J16="BUY",$J16="SELL"),ISNUMBER($AK16)),$AK16,"") -> 0.054189 | AV16: =IF(ISNUMBER($AT16),ABS(IF(ISNUMBER($I16),$I16,0)-Settings!$B$24),"") -> 0.35 | AW16: =IF(ISNUMBER($AV16),$AV16*$AT16,"") -> 0.01897 | AX16: =IF(ISNUMBER($AU16),ABS(IF(ISNUMBER($I16),$I16,0)-Settings!$B$24),"") -> 0.35 | AY16: FROZEN | AZ16: =IF($A16="","",IFERROR(INDEX(Company_List!$H$3:$H$207,MATCH($A16,Company_List!$A$3:$A$207,0)),"unassigned")) -> Information Technology | BC16: =IF($A16="","",IF(COUNTIFS($A$3:$A16,$A16,$C$3:$C16,$C16,$D$3:$D16,$D16,$G$3:$G16,$G16)=1,1,0)) -> 1 | BG16: no | BK16: =IF(OR($H16<>"Human",$S16="",$J16="",$Y16="",$Z16=""),"",IF(EXACT(UPPER($J16),UPPER($Y16)),1,0)) -> 0 | BL16: assumed - no rater record | BM16: 6 | BN16: not publisher-identified | BO16: not publisher-identified | BP16: no | BQ16: yes | BS16: YES
A17: Nvidia | B17: =IF(A17="","",_xlfn.XLOOKUP(A17, Company_List!$A:$A, Company_List!$B:$B, "")) -> NVDA | C17: 2025 | D17: Q3 | E17: All | F17: All | G17: Dragos | H17: Human | I17: 0.6 | J17: =IF(OR(I17="",Settings!$B$6=""),"",IF(I17>Settings!$B$6,"BUY",IF(I17<-Settings!$B$6,"SELL","HOLD"))) -> BUY | K17: 40 | L17: 45896 | M17: 45896 | N17: 181.6 | O17: 45897 | P17: 180.82 | Q17: =IF(OR(N17="",P17=""),"",ROUND((P17-N17)/N17,4)) -> -0.0043 | R17: =IF(OR(N17="",P17=""),"",IF(Q17>Settings!$B$3/100,"UP",IF(Q17<-Settings!$B$3/100,"DOWN","FLAT"))) -> FLAT | S17: =IF(OR(N17="",P17="",J17=""),"",IF(OR(AND(J17="BUY",R17="UP"),AND(J17="SELL",R17="DOWN"),AND(J17="HOLD",R17="FLAT")),"YES","NO")) -> NO | T17: =IF(J17="","",IF(J17="BUY",1,IF(J17="SELL",-1,0))) -> 1 | U17: =IFERROR(IF(OR(J17="",N17="",P17=""),"",IF(T17=0,0,T17*Q17-Settings!$B$4/10000-IF(T17<0,Settings!$B$5/10000,0))),"") -> -0.0053 | V17: NVIDIA fiscal Q2 FY26, released 27 Aug 2025. Strong records but reaction flat (-0.43%) - correct call was HOLD. | W17: =IF($K17="","",$K17*60) -> 2400 | X17: =IF($A17="","",$A17&"|"&$C17&"|"&$D17) -> Nvidia|2025|Q3 | Y17: =IFERROR(IF($X17="","",INDEX(LLM_Data_Entry!$H$3:$H$548,MATCH($X17,INDEX(LLM_Data_Entry!$A$3:$A$548&"|"&LLM_Data_Entry!$C$3:$C$548&"|"&LLM_Data_Entry!$D$3:$D$548,0),0))),"") -> BUY | Z17: =IFERROR(IF($X17="","",INDEX(LLM_Data_Entry!$R$3:$R$548,MATCH($X17,INDEX(LLM_Data_Entry!$A$3:$A$548&"|"&LLM_Data_Entry!$C$3:$C$548&"|"&LLM_Data_Entry!$D$3:$D$548,0),0))),"") -> NO | AB17: release date + stated time in the document (rater worksheet) | AC17: NVDA | AD17: 2025-08-27 | AE17: 181.3585 | AF17: 2025-08-28 | AG17: 180.5795 | AH17: -0.0042951987 | AI17: FLAT | AJ17: NO | AK17: -0.005295 | AL17: =IF($A17="","",IFERROR(INDEX(Company_List!$G$3:$G$207,MATCH($A17,Company_List!$A$3:$A$207,0)),"unassigned")) -> P2 | AM17: Phase 2/Nvidia/Q4 2025/NVDA-Q3FY26-press-release-SEC-EX99-1.htm; Phase 2/Nvidia/Q4 2025/NVDA-Q3FY26-earnings-call-transcript-MotleyFool.html; Phase 2/Nvidia/Q4 2025/NVDA-Q3FY26-CFO-commentary-SEC-EX99-2.htm; Phase 2/Nvidia/Q3 2025/NVDA-Q2FY26-press-release-SEC-EX99-1.htm; Phase 2/Nvidia/Q3 2025/NVDA-Q2FY26-earnings-call-transcript-AlphaStreet.html; Phase 2/Nvidia/Q3 2025/NVDA-Q2FY26-CFO-commentary-SEC-EX99-2.htm | AO17: whole bundle (Document = All) | AP17: =IF($A17="","",IF(COUNTIFS(LLM_Data_Entry!$A$3:$A$548,$A17)>0,"YES","NO")) -> YES | AQ17: =IF($A17="","",IF(COUNTIFS($A$3:$A17,$A17,$C$3:$C17,$C17,$D$3:$D17,$D17)=1,"YES","NO")) -> YES | AR17: =IF($A17="","",IF(AND($C17&"-"&$D17>=Settings!$B$19,$C17&"-"&$D17<=Settings!$B$20),"IN","OUT")) -> IN | AS17: =IF($A17="","",IF($F17="Financial Results","financials",IF($F17="Outlook/Guidance","guidance",IF($F17="Transcript Q&A","qanda",IF($F17="","unrecorded",IF($E17="All","full",IF($E17="","unrecorded",LOWER($E17)&" only"))))))) -> full | AT17: =IF(AND(OR($J17="BUY",$J17="SELL"),ISNUMBER($U17)),$U17,"") -> -0.0053 | AU17: =IF(AND(OR($J17="BUY",$J17="SELL"),ISNUMBER($AK17)),$AK17,"") -> -0.005295 | AV17: =IF(ISNUMBER($AT17),ABS(IF(ISNUMBER($I17),$I17,0)-Settings!$B$24),"") -> 0.6 | AW17: =IF(ISNUMBER($AV17),$AV17*$AT17,"") -> -0.00318 | AX17: =IF(ISNUMBER($AU17),ABS(IF(ISNUMBER($I17),$I17,0)-Settings!$B$24),"") -> 0.6 | AY17: FROZEN | AZ17: =IF($A17="","",IFERROR(INDEX(Company_List!$H$3:$H$207,MATCH($A17,Company_List!$A$3:$A$207,0)),"unassigned")) -> Information Technology | BC17: =IF($A17="","",IF(COUNTIFS($A$3:$A17,$A17,$C$3:$C17,$C17,$D$3:$D17,$D17,$G$3:$G17,$G17)=1,1,0)) -> 1 | BG17: no | BK17: =IF(OR($H17<>"Human",$S17="",$J17="",$Y17="",$Z17=""),"",IF(EXACT(UPPER($J17),UPPER($Y17)),1,0)) -> 1 | BL17: assumed - blind unless stated otherwise; the note names the realised move (query E-a, settled 10 Aug 2026) | BM17: 6 | BN17: The Motley Fool | BO17: free to read, copyright asserted | BP17: no | BQ17: yes | BS17: YES
A18: Nvidia | B18: =IF(A18="","",_xlfn.XLOOKUP(A18, Company_List!$A:$A, Company_List!$B:$B, "")) -> NVDA | C18: 2025 | D18: Q4 | E18: All | F18: All | G18: Dragos | H18: Human | I18: 0.75 | J18: =IF(OR(I18="",Settings!$B$6=""),"",IF(I18>Settings!$B$6,"BUY",IF(I18<-Settings!$B$6,"SELL","HOLD"))) -> BUY | K18: 44 | L18: 45980 | M18: 45980 | N18: 186.52 | O18: 45981 | P18: 195.95 | Q18: =IF(OR(N18="",P18=""),"",ROUND((P18-N18)/N18,4)) -> 0.0506 | R18: =IF(OR(N18="",P18=""),"",IF(Q18>Settings!$B$3/100,"UP",IF(Q18<-Settings!$B$3/100,"DOWN","FLAT"))) -> UP | S18: =IF(OR(N18="",P18="",J18=""),"",IF(OR(AND(J18="BUY",R18="UP"),AND(J18="SELL",R18="DOWN"),AND(J18="HOLD",R18="FLAT")),"YES","NO")) -> YES | T18: =IF(J18="","",IF(J18="BUY",1,IF(J18="SELL",-1,0))) -> 1 | U18: =IFERROR(IF(OR(J18="",N18="",P18=""),"",IF(T18=0,0,T18*Q18-Settings!$B$4/10000-IF(T18<0,Settings!$B$5/10000,0))),"") -> 0.0496 | V18: NVIDIA fiscal Q3 FY26, released 19 Nov 2025. Strongest print of the four; +5.1% overnight. | W18: =IF($K18="","",$K18*60) -> 2640 | X18: =IF($A18="","",$A18&"|"&$C18&"|"&$D18) -> Nvidia|2025|Q4 | Y18: =IFERROR(IF($X18="","",INDEX(LLM_Data_Entry!$H$3:$H$548,MATCH($X18,INDEX(LLM_Data_Entry!$A$3:$A$548&"|"&LLM_Data_Entry!$C$3:$C$548&"|"&LLM_Data_Entry!$D$3:$D$548,0),0))),"") -> BUY | Z18: =IFERROR(IF($X18="","",INDEX(LLM_Data_Entry!$R$3:$R$548,MATCH($X18,INDEX(LLM_Data_Entry!$A$3:$A$548&"|"&LLM_Data_Entry!$C$3:$C$548&"|"&LLM_Data_Entry!$D$3:$D$548,0),0))),"") -> YES | AB18: release date + stated time in the document (rater worksheet) | AC18: NVDA | AD18: 2025-11-19 | AE18: 186.2824 | AF18: 2025-11-20 | AG18: 195.7004 | AH18: 0.050557553 | AI18: UP | AJ18: YES | AK18: 0.049558 | AL18: =IF($A18="","",IFERROR(INDEX(Company_List!$G$3:$G$207,MATCH($A18,Company_List!$A$3:$A$207,0)),"unassigned")) -> P2 | AM18: Phase 2/Nvidia/Q4 2025/NVDA-Q3FY26-press-release-SEC-EX99-1.htm; Phase 2/Nvidia/Q4 2025/NVDA-Q3FY26-earnings-call-transcript-MotleyFool.html; Phase 2/Nvidia/Q4 2025/NVDA-Q3FY26-CFO-commentary-SEC-EX99-2.htm; Phase 2/Nvidia/Q1 2025/NVDA-Q4FY25-press-release-SEC-EX99-1.htm; Phase 2/Nvidia/Q1 2025/NVDA-Q4FY25-earnings-call-transcript-MotleyFool.html; Phase 2/Nvidia/Q1 2025/NVDA-Q4FY25-CFO-commentary-SEC-EX99-2.htm | AO18: whole bundle (Document = All) | AP18: =IF($A18="","",IF(COUNTIFS(LLM_Data_Entry!$A$3:$A$548,$A18)>0,"YES","NO")) -> YES | AQ18: =IF($A18="","",IF(COUNTIFS($A$3:$A18,$A18,$C$3:$C18,$C18,$D$3:$D18,$D18)=1,"YES","NO")) -> YES | AR18: =IF($A18="","",IF(AND($C18&"-"&$D18>=Settings!$B$19,$C18&"-"&$D18<=Settings!$B$20),"IN","OUT")) -> IN | AS18: =IF($A18="","",IF($F18="Financial Results","financials",IF($F18="Outlook/Guidance","guidance",IF($F18="Transcript Q&A","qanda",IF($F18="","unrecorded",IF($E18="All","full",IF($E18="","unrecorded",LOWER($E18)&" only"))))))) -> full | AT18: =IF(AND(OR($J18="BUY",$J18="SELL"),ISNUMBER($U18)),$U18,"") -> 0.0496 | AU18: =IF(AND(OR($J18="BUY",$J18="SELL"),ISNUMBER($AK18)),$AK18,"") -> 0.049558 | AV18: =IF(ISNUMBER($AT18),ABS(IF(ISNUMBER($I18),$I18,0)-Settings!$B$24),"") -> 0.75 | AW18: =IF(ISNUMBER($AV18),$AV18*$AT18,"") -> 0.0372 | AX18: =IF(ISNUMBER($AU18),ABS(IF(ISNUMBER($I18),$I18,0)-Settings!$B$24),"") -> 0.75 | AY18: FROZEN | AZ18: =IF($A18="","",IFERROR(INDEX(Company_List!$H$3:$H$207,MATCH($A18,Company_List!$A$3:$A$207,0)),"unassigned")) -> Information Technology | BC18: =IF($A18="","",IF(COUNTIFS($A$3:$A18,$A18,$C$3:$C18,$C18,$D$3:$D18,$D18,$G$3:$G18,$G18)=1,1,0)) -> 1 | BG18: no | BK18: =IF(OR($H18<>"Human",$S18="",$J18="",$Y18="",$Z18=""),"",IF(EXACT(UPPER($J18),UPPER($Y18)),1,0)) -> 1 | BL18: assumed - no rater record | BM18: 6 | BN18: The Motley Fool | BO18: free to read, copyright asserted | BP18: no | BQ18: yes | BS18: YES
